Workbook

Sheet REPORT_OUTPUTS
A1: PV2 OUTPUTS | F1: {=_xlfn.TEXTAFTER(_xlfn.TEXTBEFORE(CELL("filename",A1),"]"),"[") & " TABLES"} -> PV2 (color coded).xlsx TABLES | I1: {=_xlfn.TEXTAFTER(_xlfn.TEXTBEFORE(CELL("filename",D1),"]"),"[") & " CHARTS"} -> PV2 (color coded).xlsx CHARTS
A2: Variable Name | B2: Worksheet Name | C2: Cell Reference | D2: Live Cell Value | F2: Worksheet Name | G2: Table Name | I2: Worksheet Name | J2: Chart Name
A3: clm_age_at_DOI | B3: Case Inputs | C3: B13 | D3: {=IF(OR(IF(OR(A3="", B3="", C3=""), "", INDIRECT("'" & B3 & "'!" & C3))=0, IF(OR(A3="", B3="", C3=""), "", INDIRECT("'" & B3 & "'!" & C3))=""),"",INDIRECT("'" & B3 & "'!" & C3))} -> 46.214921 | F3: PV_Summary_No_Rounding | G3: PV_Summary_No_Rounding | I3: GetBloombergDailyYieldCurve_cur | J3: WC_Disc_Rate_Chart
A4: clm_age_at_trial | B4: Case Inputs | C4: B14 | D4: {=IF(OR(IF(OR(A4="", B4="", C4=""), "", INDIRECT("'" & B4 & "'!" & C4))=0, IF(OR(A4="", B4="", C4=""), "", INDIRECT("'" & B4 & "'!" & C4))=""),"",INDIRECT("'" & B4 & "'!" & C4))} -> 50.962355
A5: clm_LE_at_DOI | B5: Case Inputs | C5: B15 | D5: {=IF(OR(IF(OR(A5="", B5="", C5=""), "", INDIRECT("'" & B5 & "'!" & C5))=0, IF(OR(A5="", B5="", C5=""), "", INDIRECT("'" & B5 & "'!" & C5))=""),"",INDIRECT("'" & B5 & "'!" & C5))} -> 33.4
A6: clm_LE_at_trial | B6: Case Inputs | C6: B16 | D6: {=IF(OR(IF(OR(A6="", B6="", C6=""), "", INDIRECT("'" & B6 & "'!" & C6))=0, IF(OR(A6="", B6="", C6=""), "", INDIRECT("'" & B6 & "'!" & C6))=""),"",INDIRECT("'" & B6 & "'!" & C6))} -> 28.652567
A7: clm_WLE | B7: Case Inputs | C7: B17 | D7: {=IF(OR(IF(OR(A7="", B7="", C7=""), "", INDIRECT("'" & B7 & "'!" & C7))=0, IF(OR(A7="", B7="", C7=""), "", INDIRECT("'" & B7 & "'!" & C7))=""),"",INDIRECT("'" & B7 & "'!" & C7))} -> 19.04
A8: clm_WLE_from_trial_full | B8: Case Inputs | C8: B18 | D8: {=IF(OR(IF(OR(A8="", B8="", C8=""), "", INDIRECT("'" & B8 & "'!" & C8))=0, IF(OR(A8="", B8="", C8=""), "", INDIRECT("'" & B8 & "'!" & C8))=""),"",INDIRECT("'" & B8 & "'!" & C8))} -> 14.292567 | E8: <round to 1 decimal
A9: clm_WLE_from_trial_int | B9: Case Inputs | C9: B19 | D9: {=IF(OR(IF(OR(A9="", B9="", C9=""), "", INDIRECT("'" & B9 & "'!" & C9))=0, IF(OR(A9="", B9="", C9=""), "", INDIRECT("'" & B9 & "'!" & C9))=""),"",INDIRECT("'" & B9 & "'!" & C9))} -> 14
A10: clm_WLE_from_trial_partial | B10: Case Inputs | C10: B20 | D10: {=IF(OR(IF(OR(A10="", B10="", C10=""), "", INDIRECT("'" & B10 & "'!" & C10))=0, IF(OR(A10="", B10="", C10=""), "", INDIRECT("'" & B10 & "'!" & C10))=""),"",INDIRECT("'" & B10 & "'!" & C10))} -> 0.29256674
A11: clm_age_at_retire | B11: Case Inputs | C11: B7 | D11: {=IF(OR(IF(OR(A11="", B11="", C11=""), "", INDIRECT("'" & B11 & "'!" & C11))=0, IF(OR(A11="", B11="", C11=""), "", INDIRECT("'" & B11 & "'!" & C11))=""),"",INDIRECT("'" & B11 & "'!" & C11))} -> 70
A12: clm_retire_from_trial_full | B12: Case Inputs | C12: B21 | D12: {=IF(OR(IF(OR(A12="", B12="", C12=""), "", INDIRECT("'" & B12 & "'!" & C12))=0, IF(OR(A12="", B12="", C12=""), "", INDIRECT("'" & B12 & "'!" & C12))=""),"",INDIRECT("'" & B12 & "'!" & C12))} -> 19.037645 | E12: <round to 1 decimal
A13: clm_retire_from_trial_int | B13: Case Inputs | C13: B22 | D13: {=IF(OR(IF(OR(A13="", B13="", C13=""), "", INDIRECT("'" & B13 & "'!" & C13))=0, IF(OR(A13="", B13="", C13=""), "", INDIRECT("'" & B13 & "'!" & C13))=""),"",INDIRECT("'" & B13 & "'!" & C13))} -> 19
A14: clm_retire_from_trial_partial | B14: Case Inputs | C14: B23 | D14: {=IF(OR(IF(OR(A14="", B14="", C14=""), "", INDIRECT("'" & B14 & "'!" & C14))=0, IF(OR(A14="", B14="", C14=""), "", INDIRECT("'" & B14 & "'!" & C14))=""),"",INDIRECT("'" & B14 & "'!" & C14))} -> 0.037645448
A15: b1e_WLE_earnings | B15: Base 1 PV Loss WLE | C15: B3 | D15: {=IF(OR(IF(OR(A15="", B15="", C15=""), "", INDIRECT("'" & B15 & "'!" & C15))=0, IF(OR(A15="", B15="", C15=""), "", INDIRECT("'" & B15 & "'!" & C15))=""),"",INDIRECT("'" & B15 & "'!" & C15))} -> 75000
A16: b1e_WLE_growth_rate | B16: Base 1 PV Loss WLE | C16: E3 | D16: {=IF(OR(IF(OR(A16="", B16="", C16=""), "", INDIRECT("'" & B16 & "'!" & C16))=0, IF(OR(A16="", B16="", C16=""), "", INDIRECT("'" & B16 & "'!" & C16))=""),"",INDIRECT("'" & B16 & "'!" & C16))} -> 0.031
A17: b1e_WLE_pretrial_loss_notax | B17: Base 1 PV Loss WLE | C17: H17 | D17: {=IF(OR(IF(OR(A17="", B17="", C17=""), "", INDIRECT("'" & B17 & "'!" & C17))=0, IF(OR(A17="", B17="", C17=""), "", INDIRECT("'" & B17 & "'!" & C17))=""),"",INDIRECT("'" & B17 & "'!" & C17))} -> 355890.41
A18: b1e_WLE_pretrial_loss_adj | B18: Base 1 PV Loss WLE | C18: G17 | D18: {=IF(OR(IF(OR(A18="", B18="", C18=""), "", INDIRECT("'" & B18 & "'!" & C18))=0, IF(OR(A18="", B18="", C18=""), "", INDIRECT("'" & B18 & "'!" & C18))=""),"",INDIRECT("'" & B18 & "'!" & C18))} -> 355890.41
A19: b1e_WLE_posttrial_loss_notax | B19: Base 1 PV Loss WLE | C19: E71 | D19: {=IF(OR(IF(OR(A19="", B19="", C19=""), "", INDIRECT("'" & B19 & "'!" & C19))=0, IF(OR(A19="", B19="", C19=""), "", INDIRECT("'" & B19 & "'!" & C19))=""),"",INDIRECT("'" & B19 & "'!" & C19))} -> 1143472.7
A20: b1e_WLE_posttrial_loss_adj | B20: Base 1 PV Loss WLE | C20: G71 | D20: {=IF(OR(IF(OR(A20="", B20="", C20=""), "", INDIRECT("'" & B20 & "'!" & C20))=0, IF(OR(A20="", B20="", C20=""), "", INDIRECT("'" & B20 & "'!" & C20))=""),"",INDIRECT("'" & B20 & "'!" & C20))} -> 1091913
A21: b1e_toage_earnings | B21: Base 1 PV Loss To Age | C21: B3 | D21: {=IF(OR(IF(OR(A21="", B21="", C21=""), "", INDIRECT("'" & B21 & "'!" & C21))=0, IF(OR(A21="", B21="", C21=""), "", INDIRECT("'" & B21 & "'!" & C21))=""),"",INDIRECT("'" & B21 & "'!" & C21))} -> 141416
A22: b1e_toage_growth_rate | B22: Base 1 PV Loss To Age | C22: E3 | D22: {=IF(OR(IF(OR(A22="", B22="", C22=""), "", INDIRECT("'" & B22 & "'!" & C22))=0, IF(OR(A22="", B22="", C22=""), "", INDIRECT("'" & B22 & "'!" & C22))=""),"",INDIRECT("'" & B22 & "'!" & C22))} -> 0.0356
A23: b1e_toage_pretrial_loss_notax | B23: Base 1 PV Loss To Age | C23: H17 | D23: {=IF(OR(IF(OR(A23="", B23="", C23=""), "", INDIRECT("'" & B23 & "'!" & C23))=0, IF(OR(A23="", B23="", C23=""), "", INDIRECT("'" & B23 & "'!" & C23))=""),"",INDIRECT("'" & B23 & "'!" & C23))} -> 671047.98
A24: b1e_toage_pretrial_loss_adj | B24: Base 1 PV Loss To Age | C24: G17 | D24: {=IF(OR(IF(OR(A24="", B24="", C24=""), "", INDIRECT("'" & B24 & "'!" & C24))=0, IF(OR(A24="", B24="", C24=""), "", INDIRECT("'" & B24 & "'!" & C24))=""),"",INDIRECT("'" & B24 & "'!" & C24))} -> 671047.98
... A43: b2e_WLE_total_loss_notax | B43: Base 2 PV Loss WLE | C43: E73 | D43: {=IF(OR(IF(OR(A43="", B43="", C43=""), "", INDIRECT("'" & B43 & "'!" & C43))=0, IF(OR(A43="", B43="", C43=""), "", INDIRECT("'" & B43 & "'!" & C43))=""),"",INDIRECT("'" & B43 & "'!" & C43))} -> 2827119.2
A44: b2e_WLE_total_loss_adj | B44: Base 2 PV Loss WLE | C44: G73 | D44: {=IF(OR(IF(OR(A44="", B44="", C44=""), "", INDIRECT("'" & B44 & "'!" & C44))=0, IF(OR(A44="", B44="", C44=""), "", INDIRECT("'" & B44 & "'!" & C44))=""),"",INDIRECT("'" & B44 & "'!" & C44))} -> 2729900.8 | F44: DR for bases are WLE years (rounded up) from Bloomberg
A45: b2e_toage_total_loss_notax | B45: Base 2 PV Loss To Age | C45: E73 | D45: {=IF(OR(IF(OR(A45="", B45="", C45=""), "", INDIRECT("'" & B45 & "'!" & C45))=0, IF(OR(A45="", B45="", C45=""), "", INDIRECT("'" & B45 & "'!" & C45))=""),"",INDIRECT("'" & B45 & "'!" & C45))} -> 6128285.9 | F45: fraction of year multiplied by highest rate to get actual
A46: b2e_toage_total_loss_adj | B46: Base 2 PV Loss To Age | C46: G73 | D46: {=IF(OR(IF(OR(A46="", B46="", C46=""), "", INDIRECT("'" & B46 & "'!" & C46))=0, IF(OR(A46="", B46="", C46=""), "", INDIRECT("'" & B46 & "'!" & C46))=""),"",INDIRECT("'" & B46 & "'!" & C46))} -> 5923226
A47: b3e_WLE_earnings | B47: Base 3 PV Loss WLE | C47: B3 | D47: {=IF(OR(IF(OR(A47="", B47="", C47=""), "", INDIRECT("'" & B47 & "'!" & C47))=0, IF(OR(A47="", B47="", C47=""), "", INDIRECT("'" & B47 & "'!" & C47))=""),"",INDIRECT("'" & B47 & "'!" & C47))} -> #REF!
A48: b3e_WLE_growth_rate | B48: Base 3 PV Loss WLE | C48: E3 | D48: {=IF(OR(IF(OR(A48="", B48="", C48=""), "", INDIRECT("'" & B48 & "'!" & C48))=0, IF(OR(A48="", B48="", C48=""), "", INDIRECT("'" & B48 & "'!" & C48))=""),"",INDIRECT("'" & B48 & "'!" & C48))} -> #REF!
A49: b3e_WLE_pretrial_loss_notax | B49: Base 3 PV Loss WLE | C49: H17 | D49: {=IF(OR(IF(OR(A49="", B49="", C49=""), "", INDIRECT("'" & B49 & "'!" & C49))=0, IF(OR(A49="", B49="", C49=""), "", INDIRECT("'" & B49 & "'!" & C49))=""),"",INDIRECT("'" & B49 & "'!" & C49))} -> #REF!
A50: b3e_WLE_pretrial_loss_adj | B50: Base 3 PV Loss WLE | C50: G17 | D50: {=IF(OR(IF(OR(A50="", B50="", C50=""), "", INDIRECT("'" & B50 & "'!" & C50))=0, IF(OR(A50="", B50="", C50=""), "", INDIRECT("'" & B50 & "'!" & C50))=""),"",INDIRECT("'" & B50 & "'!" & C50))} -> #REF!
A51: b3e_WLE_posttrial_loss_notax | B51: Base 3 PV Loss WLE | C51: E71 | D51: {=IF(OR(IF(OR(A51="", B51="", C51=""), "", INDIRECT("'" & B51 & "'!" & C51))=0, IF(OR(A51="", B51="", C51=""), "", INDIRECT("'" & B51 & "'!" & C51))=""),"",INDIRECT("'" & B51 & "'!" & C51))} -> #REF!
A52: b3e_WLE_posttrial_loss_adj | B52: Base 3 PV Loss WLE | C52: G71 | D52: {=IF(OR(IF(OR(A52="", B52="", C52=""), "", INDIRECT("'" & B52 & "'!" & C52))=0, IF(OR(A52="", B52="", C52=""), "", INDIRECT("'" & B52 & "'!" & C52))=""),"",INDIRECT("'" & B52 & "'!" & C52))} -> #REF!
A53: b3e_toage_earnings | B53: Base 3 PV Loss To Age | C53: B3 | D53: {=IF(OR(IF(OR(A53="", B53="", C53=""), "", INDIRECT("'" & B53 & "'!" & C53))=0, IF(OR(A53="", B53="", C53=""), "", INDIRECT("'" & B53 & "'!" & C53))=""),"",INDIRECT("'" & B53 & "'!" & C53))} -> #REF!
A54: b3e_toage_growth_rate | B54: Base 3 PV Loss To Age | C54: E3 | D54: {=IF(OR(IF(OR(A54="", B54="", C54=""), "", INDIRECT("'" & B54 & "'!" & C54))=0, IF(OR(A54="", B54="", C54=""), "", INDIRECT("'" & B54 & "'!" & C54))=""),"",INDIRECT("'" & B54 & "'!" & C54))} -> #REF!
A55: b3e_toage_pretrial_loss_notax | B55: Base 3 PV Loss To Age | C55: H17 | D55: {=IF(OR(IF(OR(A55="", B55="", C55=""), "", INDIRECT("'" & B55 & "'!" & C55))=0, IF(OR(A55="", B55="", C55=""), "", INDIRECT("'" & B55 & "'!" & C55))=""),"",INDIRECT("'" & B55 & "'!" & C55))} -> #REF!
A56: b3e_toage_pretrial_loss_adj | B56: Base 3 PV Loss To Age | C56: G17 | D56: {=IF(OR(IF(OR(A56="", B56="", C56=""), "", INDIRECT("'" & B56 & "'!" & C56))=0, IF(OR(A56="", B56="", C56=""), "", INDIRECT("'" & B56 & "'!" & C56))=""),"",INDIRECT("'" & B56 & "'!" & C56))} -> #REF!
A57: b3e_toage_posttrial_loss_notax | B57: Base 3 PV Loss To Age | C57: E71 | D57: {=IF(OR(IF(OR(A57="", B57="", C57=""), "", INDIRECT("'" & B57 & "'!" & C57))=0, IF(OR(A57="", B57="", C57=""), "", INDIRECT("'" & B57 & "'!" & C57))=""),"",INDIRECT("'" & B57 & "'!" & C57))} -> #REF!
... A94: b5e_toage_total_loss_adj | B94: Base 5 PV Loss To Age | C94: G73 | D94: {=IF(OR(IF(OR(A94="", B94="", C94=""), "", INDIRECT("'" & B94 & "'!" & C94))=0, IF(OR(A94="", B94="", C94=""), "", INDIRECT("'" & B94 & "'!" & C94))=""),"",INDIRECT("'" & B94 & "'!" & C94))} -> 637610.72
...

Sheet Case Inputs
A1: CASE INFORMATION
A3: Plaintiff Name: | B3: Jane Doe
A4: Date of Birth (DOB): | B4: 27560
A5: Date of Accident (DOA): | B5: 44440
A6: Date of Trial (DOT): | B6: =DATE(2026,6,1) -> 46174
A7: Retirement Age: | B7: 70
A8: Gender (M/F): | B8: m
A9: Education Level: | B9: Bachelor's Degree
A10: Base Annual Earnings: | B10: 141416
A12: CALCULATED VALUES
A13: Age at Accident: | B13: =IF(OR(B5="",B4=""),"",(B5-B4)/365.25) -> 46.214921
A14: Age at Trial: | B14: =IF(OR(B6="",B4=""),"",(B6-B4)/365.25) -> 50.962355
A15: Life Expectancy at Accident: | B15: =IF(B13="","",IF(UPPER(B8)="F",_xlfn.XLOOKUP(INT(B13),LE_F!A:A,LE_F!B:B,""),IF(UPPER(B8)="M",_xlfn.XLOOKUP(INT(B13),LE_M!A:A,LE_M!B:B,""),""))) -> 33.4
A16: Life Expectancy at Trial: | B16: =IF(OR(B15="",B13="",B14=""),"",B15-(B14-B13)) -> 28.652567
A17: Work Life Expectancy (WLE): | B17: {=IF(OR(B8="",B9="",B13=""),"",_xlfn.XLOOKUP(1,(WLE!A:A=B9)*(WLE!B:B=UPPER(LEFT(B8,1)))*(WLE!C:C=INT(B13)),WLE!D:D,""))} -> 19.04
A18: WLE at Trial: | B18: =IF(OR(B17="",B13="",B14=""),"",MAX(0,B17-(B14-B13))) -> 14.292567
A19: Full Years for PV Calc: | B19: =IF(B18="","",INT(B18)) -> 14
A20: Partial Year Fraction: | B20: =IF(B18="","",B18-INT(B18)) -> 0.29256674
A21: Years to Retirement (from Trial): | B21: =MAX(0, B7 - B14) -> 19.037645
A22: Full Years (Retirement): | B22: =INT(B21) -> 19
A23: Partial Year (Retirement): | B23: =B21-B22 -> 0.037645448
A24: Years from Accident to Trial: | B24: =(B6-B5)/365.25 -> 4.7474333
A25: Full Pre-Trial Years: | B25: =INT(B24) -> 4
A26: ASSUMPTIONS
A27: Growth Rate: | B27: 0.031
A28: Pre-Trial Method: | B28: Custom Rate | C28: ← Options: "CPI Adjustment", "No Adjustment", or "Custom Rate"
A29: Custom/Interest Rate: | B29: 0
A33: Base 1 SCENARIOS
A34: WLE Scenario:
A35: Pre-Trial Loss: | B35: ='Base 1 PV Loss WLE'!G17 -> 355890.41
A36: Pre-Trial Credit (Actual Earnings)
A37: Post-Trial Loss: | B37: ='Base 1 PV Loss WLE'!G71 -> 1091913
A38: Post-Trial Credit 1 (Low Earning Capacity)
A39: Post-Trial Credit 2 (High Earning Capacity)
A40: TOTAL - WLE: | B40: ='Base 1 PV Loss WLE'!G73 -> 1447803.4
A41: To Age Scenario:
A42: Pre-Trial Loss: | B42: ='Base 1 PV Loss To Age'!G17 -> 671047.98
A43: Post-Trial Loss: | B43: ='Base 1 PV Loss To Age'!G71 -> 2799954.6
A44: TOTAL - To Age: | B44: ='Base 1 PV Loss To Age'!G73 -> 3471002.6
A46: BASE 2 SCENARIOS
...

Sheet Inputs
E1: Include
A2: Report Date | B2: 46106
A3: Attorney Salutation | B3: [[attorney_salutation]] | C3: Year | D3: Earnings
A4: Attorney First Name | B4: [[
A5: Attorney Last Name | B5: Smith
A6: Law Firm | B6: Smith & Associates LLP
A7: Street Address | B7: 123 Main Street
A8: City | B8: Miami
A9: State | B9: FL
A10: Zipcode | B10: 33101
A11: VIA EMAIL: | B11: jsmith@smithlaw.com
A12: Claimant Salutation | B12: [[claimant_salutation]]
A13: Claimant First Name | B13: [[claimant_name_first]]
A14: Claimant Last Name | B14: [[claimant_name_last]] | C14: Spouse Name | D14: Rodney | E14: FALSE
A15: Date of Birth | B15: [[claimant_DOB_short]] | C15: Spouse DOB | D15: 27983 | E15: FALSE
A16: Date of Accident | B16: [[claimant_DOI_short]] | C16: Employment Status | D16: Full-Time | E16: FALSE
A17: ="Date of "&B19 -> Date of Trial | B17: [[trial_date]] | C17: Youngest Child Name | D17: Derrick | E17: FALSE
A18: Place of Trial | B18: [[court_jurisdiction]] | C18: Youngest Child DOB | D18: 45145 | E18: FALSE
A19: Trial or Reference? (TRUE=Trial) | B19: Trial | L19: Functionally: life expectancy from trial + age at trial
A20: Documents Reviewed | B20: Tax Returns 2020-2024, W-2s from ABC, Co. Inc; Schedule C's and the Claimant Information Sheet. | C20: Occupation at time of accident employed by | D20: Plumber for ABC, Inc
A21: --- SUMMARY TOGGLES --- | D21: OPTIONS | L21: Age at accident is calculated = LE from accident
A22: Summary Item | C22: Include? | D22: Discount Rate WLE | E22: {=MIN(IF(ISNUMBER('Base 1 PV Loss WLE'!D20:D49),'Base 1 PV Loss WLE'!D20:D49))} -> 0.02289 | F22: {=MAX(IF(ISNUMBER('Base 1 PV Loss WLE'!D20:D49),'Base 1 PV Loss WLE'!D20:D49))} -> 0.03297
A23: ="Base 1: "&TEXT(B87,"$#,##0") -> Base 1: $67,453 | C23: TRUE | D23: Discount Rate to Age | E23: {=MIN(IF(ISNUMBER('Base 1 PV Loss To Age'!D20:D49),'Base 1 PV Loss To Age'!D20:D49))} -> 0.02289 | F23: {=MAX(IF(ISNUMBER('Base 1 PV Loss To Age'!D20:D49),'Base 1 PV Loss To Age'!D20:D49))} -> 0.03927 | L23: If LCP with annual costs is present, number is pulled from LCP report instead
A24: ="Loss To "&$B$19 -> Loss To Trial | B24: 225000 | C24: TRUE
A25: ="Fringe Benefits Loss To "&$B$19 -> Fringe Benefits Loss To Trial | B25: 25000 | C25: TRUE | L25: If only earnings, LE at trial (calculated using LE from accident) + age at trial
A26: ="Meal Cost to "&$B$19 -> Meal Cost to Trial | B26: 5000 | C26: TRUE
A27: ="Household Service Loss To "&$B$19 -> Household Service Loss To Trial | B27: 35000 | C27: TRUE
A28: Without return to gainful employment | C28: FALSE
A29: ="After Credit 1: "&TEXT(B88,"$#,##0") -> After Credit 1: $141,416 | C29: FALSE
A30: ="After Credit 2: "&TEXT(B89,"$#,##0") -> After Credit 2: $250,000 | C30: FALSE
A31: ="After Credit 3: "&TEXT(B90,"$#,##0") -> After Credit 3: $75,000 | C31: FALSE
A32: ="Fringe Benefits Loss From "&$B$19 -> Fringe Benefits Loss From Trial | B32: 18000 | C32: FALSE
A33: ="Employer Meals from "&$B$19 -> Employer Meals from Trial | B33: 4500 | C33: FALSE
A34: --- BASE 2 SUMMARY TOGGLES ---
A35: ="Base 2: "&TEXT(B91,"$#,##0") -> Base 2: $75,000 | C35: TRUE
A36: ="Loss To "&$B$19 -> Loss To Trial | B36: 145000 | C36: FALSE
A37: ="Fringe Benefits Loss To "&$B$19 -> Fringe Benefits Loss To Trial | B37: 24000 | C37: FALSE
A38: ="Meal Cost to "&$B$19 -> Meal Cost to Trial | B38: 4800 | C38: FALSE
A39: ="Household Service Loss To "&$B$19 -> Household Service Loss To Trial | B39: 33000 | C39: FALSE
A40: Without return to gainful employment | C40: FALSE
...

Sheet ReportSections
A1: Section
A2: I. | B2: Introduction
B3: ="Here are the estimates you have requested with respect to the diminution of earning capacity and associated economic impairment sustained by your client. The following records were considered in connection with the opinion below: "&Inputs!B20&"." -> Here are the estimates you have requested with respect to the diminution of earning capacity and associated economic impairment sustained by your client. The following records were considered in connection with the opinion below: Tax Returns 2020-2024, W-2s from ABC, Co. Inc; Schedule C's and the Claimant Information Sheet..
A4: II. | B4: Summary Results
B5: {=_xlfn.TEXTJOIN(CHAR(10),TRUE, IF(Inputs!C23=TRUE,REPT(" ",10)&Inputs!A23&REPT(" ",10),""), IF(Inputs!C24=TRUE,"• "&Inputs!A24&IF(ISNUMBER(Inputs!B24),": "&TEXT(Inputs!B24,"$#,##0"),""),""), IF(Inputs!C25=TRUE,"• "&Inputs!A25&IF(ISNUMBER(Inputs!B25),": "&TEXT(Inputs!B25,"$#,##0"),""),""), IF(Inputs!C26=TRUE,"• "&Inputs!A26&IF(ISNUMBER(Inputs!B26),": "&TEXT(Inputs!B26,"$#,##0"),""),""), IF(Inputs!C27=TRUE,"• "&Inputs!A27&IF(ISNUMBER(Inputs!B27),": "&TEXT(Inputs!B27,"$#,##0"),""),""), IF(Inputs!C28=TRUE,"• "&Inputs!A28&IF(ISNUMBER(Inputs!B28),": "&TEXT(Inputs!B28,"$#,##0"),""),""), IF(Inputs!C29=TRUE,"• "&Inputs!A29&IF(ISNUMBER(Inputs!B29),": "&TEXT(Inputs!B29,"$#,##0"),""),""), IF(Inputs!C30=TRUE,"• "&Inputs!A30&IF(ISNUMBER(Inputs!B30),": "&TEXT(Inputs!B30,"$#,##0"),""),""), IF(Inputs!C31=TRUE,"• "&Inputs!A31&IF(ISNUMBER(Inputs!B31),": "&TEXT(Inputs!B31,"$#,##0"),""),""), IF(Inputs!C32=TRUE,"• "&Inputs!A32&IF(ISNUMBER(Inputs!B32),": "&TEXT(Inputs!B32,"$#,##0"),""),""), IF(Inputs!C33=TRUE,"• "&Inputs!A33&IF(ISNUMBER(Inputs!B33),": "&TEXT(Inputs!B33,"$#,##0"),""),""), IF(Inputs!C35=TRUE,REPT(" ",10)&Inputs!A35&REPT(" ",10),""), IF(Inputs!C36=TRUE,"• "&Inputs!A36&IF(ISNUMBER(Inputs!B36),": "&TEXT(Inputs!B36,"$#,##0"),""),""), IF(Inputs!C37=TRUE,"• "&Inputs!A37&IF(ISNUMBER(Inputs!B37),": "&TEXT(Inputs!B37,"$#,##0"),""),""), IF(Inputs!C38=TRUE,"• "&Inputs!A38&IF(ISNUMBER(Inputs!B38),": "&TEXT(Inputs!B38,"$#,##0"),""),""), IF(Inputs!C39=TRUE,"• "&Inputs!A39&IF(ISNUMBER(Inputs!B39),": "&TEXT(Inputs!B39,"$#,##0"),""),""), IF(Inputs!C40=TRUE,"• "&Inputs!A40&IF(ISNUMBER(Inputs!B40),": "&TEXT(Inputs!B40,"$#,##0"),""),""), IF(Inputs!C41=TRUE,"• "&Inputs!A41&IF(ISNUMBER(Inputs!B41),": "&TEXT(Inputs!B41,"$#,##0"),""),""), IF(Inputs!C42=TRUE,"• "&Inputs!A42&IF(ISNUMBER(Inputs!B42),": "&TEXT(Inputs!B42,"$#,##0"),""),""), IF(Inputs!C43=TRUE,"• "&Inputs!A43&IF(ISNUMBER(Inputs!B43),": "&TEXT(Inputs!B43,"$#,##0"),""),""), IF(Inputs!C44=TRUE,"• "&Inputs!A44&IF(ISNUMBER(Inputs!B44),": "&TEXT(Inputs!B44,"$#,##0"),""),""), IF(Inputs!C45=TRUE,"• "&Inputs!A45&IF(ISNUMBER(Inputs!B45),": "&TEXT(Inputs!B45,"$#,##0"),""),""), IF(Inputs!C47=TRUE,REPT(" ",10)&Inputs!A47&REPT(" ",10),""), IF(Inputs!C48=TRUE,"• "&Inputs!A48&IF(ISNUMBER(Inputs!B48),": "&TEXT(Inputs!B48,"$#,##0"),""),""), IF(Inputs!C49=TRUE,"• "&Inputs!A49&IF(ISNUMBER(Inputs!B49),": "&TEXT(Inputs!B49,"$#,##0"),""),""), IF(Inputs!C50=TRUE,"• "&Inputs!A50&IF(ISNUMBER(Inputs!B50),": "&TEXT(Inputs!B50,"$#,##0"),""),""), IF(Inputs!C51=TRUE,"• "&Inputs!A51&IF(ISNUMBER(Inputs!B51),": "&TEXT(Inputs!B51,"$#,##0"),""),""), IF(Inputs!C52=TRUE,"• "&Inputs!A52&IF(ISNUMBER(Inputs!B52),": "&TEXT(Inputs!B52,"$#,##0"),""),""), IF(Inputs!C53=TRUE,"• "&Inputs!A53&IF(ISNUMBER(Inputs!B53),": "&TEXT(Inputs!B53,"$#,##0"),""),""), IF(Inputs!C54=TRUE,"• "&Inputs!A54&IF(ISNUMBER(Inputs!B54),": "&TEXT(Inputs!B54,"$#,##0"),""),""), IF(Inputs!C55=TRUE,"• "&Inputs!A55&IF(ISNUMBER(Inputs!B55),": "&TEXT(Inputs!B55,"$#,##0"),""),""), IF(Inputs!C56=TRUE,"• "&Inputs!A56&IF(ISNUMBER(Inputs!B56),": "&TEXT(Inputs!B56,"$#,##0"),""),""), IF(Inputs!C57=TRUE,"• "&Inputs!A57&IF(ISNUMBER(Inputs!B57),": "&TEXT(Inputs!B57,"$#,##0"),""),""), IF(Inputs!C59=TRUE,REPT(" ",10)&Inputs!A59&REPT(" ",10),""), IF(Inputs!C60=TRUE,"• "&Inputs!A60&IF(ISNUMBER(Inputs!B60),": "&TEXT(Inputs!B60,"$#,##0"),""),""), IF(Inputs!C61=TRUE,"• "&Inputs!A61&IF(ISNUMBER(Inputs!B61),": "&TEXT(Inputs!B61,"$#,##0"),""),""), IF(Inputs!C62=TRUE,"• "&Inputs!A62&IF(ISNUMBER(Inputs!B62),": "&TEXT(Inputs!B62,"$#,##0"),""),""), IF(Inputs!C63=TRUE,"• "&Inputs!A63&IF(ISNUMBER(Inputs!B63),": "&TEXT(Inputs!B63,"$#,##0"),""),""), IF(Inputs!C64=TRUE,"• "&Inputs!A64&IF(ISNUMBER(Inputs!B64),": "&TEXT(Inputs!B64,"$#,##0"),""),""), IF(Inputs!C65=TRUE,"• "&Inputs!A65&IF(ISNUMBER(Inputs!B65),": "&TEXT(Inputs!B65,"$#,##0"),""),""), IF(Inputs!C66=TRUE,"• "&Inputs!A66&IF(ISNUMBER(Inputs!B66),": "&TEXT(Inputs!B66,"$#,##0"),""),""), IF(Inputs!C67=TRUE,"• "&Inputs!A67&IF(ISNUMBER(Inputs!B67),": "&TEXT(Inputs!B67,"$#,##0"),""),""), IF(Inputs!C68=TRUE,"• "&Inputs!A68&IF(ISNUMBER(Inputs!B68),": "&TEXT(Inputs!B68,"$#,##0"),""),""), IF(Inputs!C69=TRUE,"• "&Inputs!A69&IF(ISNUMBER(Inputs!B69),": "&TEXT(Inputs!B69,"$#,##0"),""),""), IF(Inputs!C71=TRUE,REPT(" ",10)&Inputs!A71&REPT(" ",10),""), IF(Inputs!C72=TRUE,"• "&Inputs!A72&IF(ISNUMBER(Inputs!B72),": "&TEXT(Inputs!B72,"$#,##0"),""),""), IF(Inputs!C73=TRUE,"• "&Inputs!A73&IF(ISNUMBER(Inputs!B73),": "&TEXT(Inputs!B73,"$#,##0"),""),""), IF(Inputs!C74=TRUE,"• "&Inputs!A74&IF(ISNUMBER(Inputs!B74),": "&TEXT(Inputs!B74,"$#,##0"),""),""), IF(Inputs!C75=TRUE,"• "&Inputs!A75&IF(ISNUMBER(Inputs!B75),": "&TEXT(Inputs!B75,"$#,##0"),""),""), IF(Inputs!C76=TRUE,"• "&Inputs!A76&IF(ISNUMBER(Inputs!B76),": "&TEXT(Inputs!B76,"$#,##0"),""),""), IF(Inputs!C77=TRUE,"• "&Inputs!A77&IF(ISNUMBER(Inputs!B77),": "&TEXT(Inputs!B77,"$#,##0"),""),""), IF(Inputs!C78=TRUE,"• "&Inputs!A78&IF(ISNUMBER(Inputs!B78),": "&TEXT(Inputs!B78,"$#,##0"),""),""), IF(Inputs!C79=TRUE,"• "&Inputs!A79&IF(ISNUMBER(Inputs!B79),": "&TEXT(Inputs!B79,"$#,##0"),""),""), IF(Inputs!C80=TRUE,"• "&Inputs!A80&IF(ISNUMBER(Inputs!B80),": "&TEXT(Inputs!B80,"$#,##0"),""),""), IF(Inputs!C81=TRUE,"• "&Inputs!A81&IF(ISNUMBER(Inputs!B81),": "&TEXT(Inputs!B81,"$#,##0"),""),""), IF(OR(Inputs!C82:C84=TRUE),REPT(" ",10)&"Future Medical Care"&REPT(" ",10),""), IF(Inputs!C82=TRUE,"• "&"Future Medical Low: "&TEXT(Inputs!B82,"$#,##0"),""), IF(Inputs!C83=TRUE,"• "&"Future Medical High: "&TEXT(Inputs!B83,"$#,##0"),""), IF(Inputs!C84=TRUE,"• "&"Future Medical Midpoint: "&TEXT(Inputs!B84,"$#,##0"),""))} -> Base 1: $67,453 • Loss To Trial: $225,000 • Fringe Benefits Loss To Trial: $25,000 • Meal Cost to Trial: $5,000 • Household Service Loss To Trial: $35,000 Base 2: $75,000
A6: III. | B6: Census Data
B7: Date of Birth: | C7: =TEXT(Inputs!B15,"mmmm d, yyyy") -> [[claimant_DOB_short]] | D7: Spouse: | E7: =Inputs!D14 -> Rodney | F7: FALSE | G7: Youngest Child: | H7: =Inputs!D17 -> Derrick | I7: FALSE
B8: Date of Accident: | C8: =TEXT(Inputs!B16,"mmmm d, yyyy") -> [[claimant_DOI_short]] | D8: Date of Birth: | E8: =TEXT(Inputs!D15,"MMMM D, YYYY") -> August 11, 1976 | F8: FALSE | G8: Date of Birth: | H8: =Inputs!D18 -> 45145 | I8: FALSE
B9: =Inputs!A17&":" -> Date of Trial: | C9: =TEXT(Inputs!B17,"mmmm d, yyyy") -> [[trial_date]] | D9: Employment Status: | E9: =Inputs!D16 -> Full-Time | F9: FALSE | G9: Other Children: | I9: FALSE
B10: Place of Trial: | C10: =Inputs!B18 -> [[court_jurisdiction]]
A11: 1 | B11: Earnings Base
B12: ="1. An Earnings Base of "&TEXT(Inputs!B87,"$#,##0")&" is employed in the estimate of earning capacity losses below. Losses are presented on an after-tax basis using an effective tax rate of "&TEXT(INDEX(Inputs!$H$87:$H$96,MATCH(Inputs!$B$87,Inputs!$F$87:$F$96,0)),"0.00%")&". " -> 1. An Earnings Base of $67,453 is employed in the estimate of earning capacity losses below. Losses are presented on an after-tax basis using an effective tax rate of 0.00%. | C12: FALSE | D12: =LEFT(B12,FIND("below",B12)+4)&"." -> 1. An Earnings Base of $67,453 is employed in the estimate of earning capacity losses below. | E12: FALSE
B13: ="1. Alternative bases of "&TEXT(Inputs!$F$87,"$#,##0")&" and "&TEXT(Inputs!$F$90,"$#,##0")&" have been employed in the estimate of earning capacity losses below. Losses are presented on an after-tax basis using an effective tax rate of "&TEXT(Inputs!$H$87,"0.00%")&" and "&TEXT(Inputs!$H$90,"0.00%")&" respectively." -> 1. Alternative bases of $75,000 and $250,000 have been employed in the estimate of earning capacity losses below. Losses are presented on an after-tax basis using an effective tax rate of 10.00% and 15.00% respectively. | C13: FALSE | D13: =LEFT(B13,FIND("below",B13)+4)&"." -> 1. Alternative bases of $75,000 and $250,000 have been employed in the estimate of earning capacity losses below. | E13: FALSE
B14: ="1. Alternative bases of "&TEXT(Inputs!$B$87,"$#,##0")&", "&TEXT(Inputs!$B$91,"$#,##0")&" and "&TEXT(Inputs!$B$95,"$#,##0")&" have been employed in the estimate of earning capacity losses below. Losses are presented on an after-tax basis using an effective tax rate of "&TEXT(Inputs!$H$87,"0.00%")&", "&TEXT(Inputs!$H$91,"0.00%")&" and "&TEXT(Inputs!$H$95,"0.00%")&" respectively. " -> 1. Alternative bases of $67,453, $75,000 and $65,777 have been employed in the estimate of earning capacity losses below. Losses are presented on an after-tax basis using an effective tax rate of 10.00%, 0.00% and 0.00% respectively. | C14: FALSE | D14: =LEFT(B14,FIND("below",B14)+4)&"." -> 1. Alternative bases of $67,453, $75,000 and $65,777 have been employed in the estimate of earning capacity losses below. | E14: FALSE
B15: ="1. An Earnings Base of "&TEXT(Inputs!B87,"$#,##0")&" grown to "&TEXT(Inputs!B91,"$#,##0")&" as of "&LOWER(Inputs!B19)&" is employed in the estimate of earning capacity losses below. Losses are presented on an after-tax basis using an effective tax rate of "&TEXT(INDEX(Inputs!$H$87:$H$96,MATCH(Inputs!$B$87,Inputs!$F$87:$F$96,0)),"0.00%")&" to "&TEXT(INDEX(Inputs!$H$87:$H$96,MATCH(Inputs!$B$91,Inputs!$F$87:$F$96,0)),"0.00%")&". " -> 1. An Earnings Base of $67,453 grown to $75,000 as of trial is employed in the estimate of earning capacity losses below. Losses are presented on an after-tax basis using an effective tax rate of 0.00% to 10.00%. | C15: FALSE
A16: 2 | B16: Loss To Trial
B17: ="2. Loss to "&LOWER(Inputs!$B$19)&" is "&TEXT(Inputs!$B$24,"$#,##0")&" under the base of "&TEXT(Inputs!$B$87,"$#,##0")&". Losses are estimated by multiplying the earnings base by the time period from "&TEXT(Inputs!$B$16,"mmmm d, yyyy")&", to "&LOWER(Inputs!$B$19)&". Earnings (unknown) since "&TEXT(Inputs!$B$16,"mmmm d, yyyy")&", should be deducted. " -> 2. Loss to trial is $225,000 under the base of $67,453. Losses are estimated by multiplying the earnings base by the time period from [[claimant_DOI_short]], to trial. Earnings (unknown) since [[claimant_DOI_short]], should be deducted. | C17: FALSE
B18: ="2. Loss to "&LOWER(Inputs!$B$19)&" is "&TEXT(Inputs!$B$24,"$#,##0")&" under the base of "&TEXT(Inputs!$F$87,"$#,##0")&" and "&TEXT(Inputs!$B$36,"$#,##0")&" under the base of "&TEXT(Inputs!$F$91,"$#,##0")&". Losses are estimated by multiplying the earnings base by the time period from "&TEXT(Inputs!$B$16,"mmmm d, yyyy")&", to "&LOWER(Inputs!$B$19)&". Earnings (unknown) since "&TEXT(Inputs!$B$16,"mmmm d, yyyy")&", should be deducted. " -> 2. Loss to trial is $225,000 under the base of $75,000 and $145,000 under the base of $67,888. Losses are estimated by multiplying the earnings base by the time period from [[claimant_DOI_short]], to trial. Earnings (unknown) since [[claimant_DOI_short]], should be deducted. | C18: FALSE
B19: ="2. Loss to "&LOWER(Inputs!$B$19)&" is "&TEXT(Inputs!$B$24,"$#,##0")&" under the base of "&TEXT(Inputs!$B$87,"$#,##0")&", "&TEXT(Inputs!$B$36,"$#,##0")&" under the base of "&TEXT(Inputs!$B$91,"$#,##0")&" and "&TEXT(Inputs!$B$48,"$#,##0")&" under the base of "&TEXT(Inputs!$B$95,"$#,##0")&". Losses are estimated by multiplying the earnings base by the time period from "&TEXT(Inputs!$B$16,"mmmm d, yyyy")&", to "&LOWER(Inputs!$B$19)&". Earnings (unknown) since "&TEXT(Inputs!$B$16,"mmmm d, yyyy")&", should be deducted. " -> 2. Loss to trial is $225,000 under the base of $67,453, $145,000 under the base of $75,000 and $140,000 under the base of $65,777. Losses are estimated by multiplying the earnings base by the time period from [[claimant_DOI_short]], to trial. Earnings (unknown) since [[claimant_DOI_short]], should be deducted. | C19: FALSE
B20: ="2. Loss to "&LOWER(Inputs!$B$19)&" is "&TEXT(Inputs!$B$24,"$#,##0")&" under the base of "&TEXT(Inputs!$B$87,"$#,##0")&" grown to "&TEXT(Inputs!$B$91,"$#,##0")&". Losses are estimated by multiplying the earnings base by the time period from "&TEXT(Inputs!$B$16,"mmmm d, yyyy")&", to "&LOWER(Inputs!$B$19)&". Earnings (unknown) since "&TEXT(Inputs!$B$16,"mmmm d, yyyy")&", should be deducted. " -> 2. Loss to trial is $225,000 under the base of $67,453 grown to $75,000. Losses are estimated by multiplying the earnings base by the time period from [[claimant_DOI_short]], to trial. Earnings (unknown) since [[claimant_DOI_short]], should be deducted. | C20: FALSE
A21: 3 | B21: Earnings and Employment Background
B22: ="1. Earnings and Employment Background indicates that your client was working as a "&Inputs!$D$20&" at the time of the accident." -> 1. Earnings and Employment Background indicates that your client was working as a Plumber for ABC, Inc at the time of the accident. | E22: FALSE
A23: 4b | B23: Discount Rates
A24: Nominal_WLE | B24: =_xlfn._LONGTEXT("Discount Rates form the basis upon which post-trial earning capacity streams are commuted to present value. The discounting ensures that the lump sum award will dissipate entirely by the end of the calculating period and will be used to replicate the stre","am of anticipated earning capacity, without windfall to your client. This analysis employs a laddered discount rate approach with rates derived from current rates of interest on AAA-rated municipal bonds ranging from ")&TEXT(Inputs!$E$22,"0.0%")&" to "&TEXT(Inputs!$F$22,"0.0%")&"." -> Discount Rates form the basis upon which post-trial earning capacity streams are commuted to present value. The discounting ensures that the lump sum award will dissipate entirely by the end of the calculating period and will be used to replicate the stream of anticipated earning capacity, without windfall to your client. This analysis employs a laddered discount rate approach with rates derived from current rates of interest on AAA-rated municipal bonds ranging from 2.3% to 3.3%. | E24: FALSE
A25: Below Mkt_WLE | B25: =CONCATENATE(_xlfn._LONGTEXT("Below Market Discount Rates form the basis upon which post-trial earning capacity streams are commuted to present value. The discounting ensures that the lump sum award will dissipate entirely by the end of the calculating period and will be used to repli","cate the stream of anticipated earning capacity, without windfall to your client. This analysis employs a laddered discount rate approach with rates derived from of current real rates of interest on AAA-rated municipal bonds adjusted for the forecased int","ermediate long run inflation estimate as reported in the Annual Report of the Board of Trustees of the Social Security Administration (2025). These rates currently range from "),TEXT(Inputs!$E$22,"0.0%")," to ",TEXT(Inputs!$F$22,"0.0%"),".") -> Below Market Discount Rates form the basis upon which post-trial earning capacity streams are commuted to present value. The discounting ensures that the lump sum award will dissipate entirely by the end of the calculating period and will be used to replicate the stream of anticipated earning capacity, without windfall to your client. This analysis employs a laddered discount rate approach with rates derived from of current real rates of interest on AAA-rated municipal bonds adjusted for the forecased intermediate long run inflation estimate as reported in the Annual Report of the Board of Trustees of the Social Security Administration (2025). These rates currently range from 2.3% to 3.3%. | E25: FALSE
A26: Nominal_To_Age | B26: =_xlfn._LONGTEXT("Discount Rates form the basis upon which post-trial earning capacity streams are commuted to present value. The discounting ensures that the lump sum award will dissipate entirely by the end of the calculating period and will be used to replicate the stre","am of anticipated earning capacity, without windfall to your client. This analysis employs a laddered discount rate approach with rates derived from current rates of interest on AAA-rated municipal bonds ranging from ")&TEXT(Inputs!$E$23,"0.0%")&" to "&TEXT(Inputs!$F$23,"0.0%")&"." -> Discount Rates form the basis upon which post-trial earning capacity streams are commuted to present value. The discounting ensures that the lump sum award will dissipate entirely by the end of the calculating period and will be used to replicate the stream of anticipated earning capacity, without windfall to your client. This analysis employs a laddered discount rate approach with rates derived from current rates of interest on AAA-rated municipal bonds ranging from 2.3% to 3.9%. | E26: FALSE

Sheet Base 1 PV Loss WLE
A1: PRESENT VALUE LOSS - BASE 1 WLE SCENARIO
A3: Base Earnings: | B3: 75000 | C3: ← either EC from Voc (AUTOMATE THIS) or stat. earnings | D3: Growth Rate: | E3: 0.031 | F3: ← INPUT | G3: <- 0 - 10 WLE = 3.10%, 11-infinity WLE = 3.56%, for federal court subtract ESTIMATED INFLATION RATE (often 2.4%, needs to be customizable) to return REAL RATE
A4: WLE at Trial: | B4: ='Case Inputs'!B18 -> 14.292567 | D4: Full Years: | E4: ='Case Inputs'!B19 -> 14
A5: Partial Year: | B5: ='Case Inputs'!B20 -> 0.29256674 | D5: Effective Tax Rate | E5: 0.1 | F5: FALSE
D6: Inflation Rate | E6: =E3 -> 0.031 | F6: FALSE
A7: PRE-TRIAL LOSSES (Accident to Trial)
A8: Year | B8: Calendar Year | C8: Loss Amount | D8: =IF('Case Inputs'!$B$28="CPI Adjustment","CPI Index",IF('Case Inputs'!$B$28="Custom Rate","","")) | E8: Growth Factor | F8: Proration Factor | G8: Adjusted Loss | H8: Unadjusted Loss
A9: =YEAR('Case Inputs'!$B$5) -> 2021 | B9: =YEAR('Case Inputs'!$B$5) -> 2021 | C9: =$B$3 -> 75000 | D9: =IF('Case Inputs'!$B$28="CPI Adjustment",IFERROR(INDEX('CPI Data'!$F$2:$F$5,MATCH(B9,'CPI Data'!$E$2:$E$5,0)),""),"") | E9: =1 -> 1 | F9: =(DATE(YEAR('Case Inputs'!$B$5),12,31)-'Case Inputs'!$B$5)/365 -> 0.33150685 | G9: =C9*F9*IF($F$5,1-$E$5,1) -> 24863.014 | H9: =C9*F9 -> 24863.014 | O9: <- LOSS TO TRIAL (IF STILL UNEMPLOYED)
A10: =IF(YEAR('Case Inputs'!$B$6)-YEAR('Case Inputs'!$B$5)>=2,YEAR('Case Inputs'!$B$5)+1,"") -> 2022 | B10: =IF(A10="","",A10) -> 2022 | C10: =C9*E10 -> 75000 | D10: =IF('Case Inputs'!$B$28="CPI Adjustment",IFERROR(INDEX('CPI Data'!$F$2:$F$5,MATCH(B10,'CPI Data'!$E$2:$E$5,0)),""),"") | E10: =IF('Case Inputs'!$B$28="CPI Adjustment",INDEX('CPI Data'!$F:$F,MATCH(B10,'CPI Data'!$E:$E,0))/INDEX('CPI Data'!$F:$F,MATCH(B9,'CPI Data'!$E:$E,0)),IF('Case Inputs'!$B$28="No Adjustment",1,1+'Case Inputs'!$B$29)) -> 1 | F10: 1 | G10: =C10*F10*IF($F$5,1-$E$5,1) -> 75000 | H10: =C10*F10 -> 75000 | O10: <- LOSS TO TRIAL - ACTUAL EARNINGS (EARNINGS SINCE DOI) IF EMPLOYED
A11: =IF(YEAR('Case Inputs'!$B$6)-YEAR('Case Inputs'!$B$5)>=3,YEAR('Case Inputs'!$B$5)+2,"") -> 2023 | B11: =IF(A11="","",A11) -> 2023 | C11: =C10*E11 -> 75000 | D11: =IF('Case Inputs'!$B$28="CPI Adjustment",IFERROR(INDEX('CPI Data'!$F$2:$F$5,MATCH(B11,'CPI Data'!$E$2:$E$5,0)),""),"") | E11: =IF('Case Inputs'!$B$28="CPI Adjustment",INDEX('CPI Data'!$F:$F,MATCH(B11,'CPI Data'!$E:$E,0))/INDEX('CPI Data'!$F:$F,MATCH(B10,'CPI Data'!$E:$E,0)),IF('Case Inputs'!$B$28="No Adjustment",1,1+'Case Inputs'!$B$29)) -> 1 | F11: 1 | G11: =C11*F11*IF($F$5,1-$E$5,1) -> 75000 | H11: =C11*F11 -> 75000
A12: =IF(YEAR('Case Inputs'!$B$6)-YEAR('Case Inputs'!$B$5)>=4,YEAR('Case Inputs'!$B$5)+3,"") -> 2024 | B12: =IF(A12="","",A12) -> 2024 | C12: =IF(A12="","",C11*E12) -> 75000 | D12: =IF(A12="","",IF('Case Inputs'!$B$28="CPI Adjustment",IFERROR(INDEX('CPI Data'!$F$2:$F$10,MATCH(B12,'CPI Data'!$E$2:$E$10,0)),""),"")) | E12: =IF(A12="","",IF('Case Inputs'!$B$28="CPI Adjustment",INDEX('CPI Data'!$F:$F,MATCH(B12,'CPI Data'!$E:$E,0))/INDEX('CPI Data'!$F:$F,MATCH(B11,'CPI Data'!$E:$E,0)),IF('Case Inputs'!$B$28="No Adjustment",1,1+'Case Inputs'!$B$29))) -> 1 | F12: =IF(A12="","",1) -> 1 | G12: =IF(A12="","",C12*F12*IF($F$5,1-$E$5,1)) -> 75000 | H12: =C12*F12 -> 75000
A13: =IF(YEAR('Case Inputs'!$B$6)-YEAR('Case Inputs'!$B$5)>=5,YEAR('Case Inputs'!$B$5)+4,"") -> 2025 | B13: =IF(A13="","",A13) -> 2025 | C13: =IF(A13="","",C12*E13) -> 75000 | D13: =IF(A13="","",IF('Case Inputs'!$B$28="CPI Adjustment",IFERROR(INDEX('CPI Data'!$F$2:$F$10,MATCH(B13,'CPI Data'!$E$2:$E$10,0)),""),"")) | E13: =IF(A13="","",IF('Case Inputs'!$B$28="CPI Adjustment",INDEX('CPI Data'!$F:$F,MATCH(B13,'CPI Data'!$E:$E,0))/INDEX('CPI Data'!$F:$F,MATCH(B12,'CPI Data'!$E:$E,0)),IF('Case Inputs'!$B$28="No Adjustment",1,1+'Case Inputs'!$B$29))) -> 1 | F13: =IF(A13="","",1) -> 1 | G13: =IF(A13="","",C13*F13*IF($F$5,1-$E$5,1)) -> 75000 | H13: =C13*F13 -> 75000
A15: =YEAR('Case Inputs'!$B$6) -> 2026 | B15: =YEAR('Case Inputs'!$B$6) -> 2026 | C15: =IF(A13<>"",C13*E15,IF(A12<>"",C12*E15,IF(A11<>"",C11*E15,IF(A10<>"",C10*E15,C9*E15)))) -> 75000 | D15: =IF('Case Inputs'!$B$28="CPI Adjustment",IFERROR(INDEX('CPI Data'!$F$2:$F$5,MATCH(B15,'CPI Data'!$E$2:$E$5,0)),""),"") | E15: =IF('Case Inputs'!$B$28="CPI Adjustment",INDEX('CPI Data'!$F:$F,MATCH(B15,'CPI Data'!$E:$E,0))/INDEX('CPI Data'!$F:$F,MATCH(IF(A13<>"",B13,IF(A12<>"",B12,IF(A11<>"",B11,IF(A10<>"",B10,B9)))),'CPI Data'!$E:$E,0)),IF('Case Inputs'!$B$28="No Adjustment",1,1+'Case Inputs'!$B$29)) -> 1 | F15: =('Case Inputs'!$B$6-DATE(YEAR('Case Inputs'!$B$6),1,1))/365 -> 0.41369863 | G15: =C15*F15*IF($F$5,1-$E$5,1) -> 31027.397 | H15: =C15*F15 -> 31027.397
A17: PRE-TRIAL SUBTOTAL | G17: =SUM(G9:G15) -> 355890.41 | H17: =SUM(H9:H15) -> 355890.41
A19: POST-TRIAL LOSSES (Trial to WLE)
A20: =IF(1>$E$4+1,"",1) -> 1 | B20: =IF(A20="","",YEAR('Case Inputs'!$B$6)+A20) -> 2027 | C20: =IF(A20="","",$C$15*(1+$E$3)^A20) -> 77325 | D20: =IF(A20="","",IFERROR(INDEX('Discount Rates'!$C:$C,MATCH(TEXT(B20,"0"),'Discount Rates'!$A:$A,0))/100-IF($F$6=TRUE,$E$6,0),0)) -> 0.02301 | E20: =IF(A20="","",C20/((1+D20)^A20)) -> 75585.771 | F20: =IF(A20="","",IF(A20<=$E$4,1,IF(A20=$E$4+1,$B$5,0))) -> 1 | G20: =IF(A20="","",E20*F20*IF($F$5,1-$E$5,1)) -> 75585.771
A21: =IF(2>$E$4+1,"",2) -> 2 | B21: =IF(A21="","",YEAR('Case Inputs'!$B$6)+A21) -> 2028 | C21: =IF(A21="","",$C$15*(1+$E$3)^A21) -> 79722.075 | D21: =IF(A21="","",IFERROR(INDEX('Discount Rates'!$C:$C,MATCH(TEXT(B21,"0"),'Discount Rates'!$A:$A,0))/100-IF($F$6=TRUE,$E$6,0),0)) -> 0.02291 | E21: =IF(A21="","",C21/((1+D21)^A21)) -> 76191.013 | F21: =IF(A21="","",IF(A21<=$E$4,1,IF(A21=$E$4+1,$B$5,0))) -> 1 | G21: =IF(A21="","",E21*F21*IF($F$5,1-$E$5,1)) -> 76191.013
A22: =IF(3>$E$4+1,"",3) -> 3 | B22: =IF(A22="","",YEAR('Case Inputs'!$B$6)+A22) -> 2029 | C22: =IF(A22="","",$C$15*(1+$E$3)^A22) -> 82193.459 | D22: =IF(A22="","",IFERROR(INDEX('Discount Rates'!$C:$C,MATCH(TEXT(B22,"0"),'Discount Rates'!$A:$A,0))/100-IF($F$6=TRUE,$E$6,0),0)) -> 0.02289 | E22: =IF(A22="","",C22/((1+D22)^A22)) -> 76798.097 | F22: =IF(A22="","",IF(A22<=$E$4,1,IF(A22=$E$4+1,$B$5,0))) -> 1 | G22: =IF(A22="","",E22*F22*IF($F$5,1-$E$5,1)) -> 76798.097
A23: =IF(4>$E$4+1,"",4) -> 4 | B23: =IF(A23="","",YEAR('Case Inputs'!$B$6)+A23) -> 2030 | C23: =IF(A23="","",$C$15*(1+$E$3)^A23) -> 84741.457 | D23: =IF(A23="","",IFERROR(INDEX('Discount Rates'!$C:$C,MATCH(TEXT(B23,"0"),'Discount Rates'!$A:$A,0))/100-IF($F$6=TRUE,$E$6,0),0)) -> 0.02346 | E23: =IF(A23="","",C23/((1+D23)^A23)) -> 77234.694 | F23: =IF(A23="","",IF(A23<=$E$4,1,IF(A23=$E$4+1,$B$5,0))) -> 1 | G23: =IF(A23="","",E23*F23*IF($F$5,1-$E$5,1)) -> 77234.694
A24: =IF(5>$E$4+1,"",5) -> 5 | B24: =IF(A24="","",YEAR('Case Inputs'!$B$6)+A24) -> 2031 | C24: =IF(A24="","",$C$15*(1+$E$3)^A24) -> 87368.442 | D24: =IF(A24="","",IFERROR(INDEX('Discount Rates'!$C:$C,MATCH(TEXT(B24,"0"),'Discount Rates'!$A:$A,0))/100-IF($F$6=TRUE,$E$6,0),0)) -> 0.02397 | E24: =IF(A24="","",C24/((1+D24)^A24)) -> 77610.133 | F24: =IF(A24="","",IF(A24<=$E$4,1,IF(A24=$E$4+1,$B$5,0))) -> 1 | G24: =IF(A24="","",E24*F24*IF($F$5,1-$E$5,1)) -> 77610.133
A25: =IF(6>$E$4+1,"",6) -> 6 | B25: =IF(A25="","",YEAR('Case Inputs'!$B$6)+A25) -> 2032 | C25: =IF(A25="","",$C$15*(1+$E$3)^A25) -> 90076.863 | D25: =IF(A25="","",IFERROR(INDEX('Discount Rates'!$C:$C,MATCH(TEXT(B25,"0"),'Discount Rates'!$A:$A,0))/100-IF($F$6=TRUE,$E$6,0),0)) -> 0.02481 | E25: =IF(A25="","",C25/((1+D25)^A25)) -> 77759.441 | F25: =IF(A25="","",IF(A25<=$E$4,1,IF(A25=$E$4+1,$B$5,0))) -> 1 | G25: =IF(A25="","",E25*F25*IF($F$5,1-$E$5,1)) -> 77759.441
A26: =IF(7>$E$4+1,"",7) -> 7 | B26: =IF(A26="","",YEAR('Case Inputs'!$B$6)+A26) -> 2033 | C26: =IF(A26="","",$C$15*(1+$E$3)^A26) -> 92869.246 | D26: =IF(A26="","",IFERROR(INDEX('Discount Rates'!$C:$C,MATCH(TEXT(B26,"0"),'Discount Rates'!$A:$A,0))/100-IF($F$6=TRUE,$E$6,0),0)) -> 0.02581 | E26: =IF(A26="","",C26/((1+D26)^A26)) -> 77696.852 | F26: =IF(A26="","",IF(A26<=$E$4,1,IF(A26=$E$4+1,$B$5,0))) -> 1 | G26: =IF(A26="","",E26*F26*IF($F$5,1-$E$5,1)) -> 77696.852
A27: =IF(8>$E$4+1,"",8) -> 8 | B27: =IF(A27="","",YEAR('Case Inputs'!$B$6)+A27) -> 2034 | C27: =IF(A27="","",$C$15*(1+$E$3)^A27) -> 95748.193 | D27: =IF(A27="","",IFERROR(INDEX('Discount Rates'!$C:$C,MATCH(TEXT(B27,"0"),'Discount Rates'!$A:$A,0))/100-IF($F$6=TRUE,$E$6,0),0)) -> 0.02646 | E27: =IF(A27="","",C27/((1+D27)^A27)) -> 77695.228 | F27: =IF(A27="","",IF(A27<=$E$4,1,IF(A27=$E$4+1,$B$5,0))) -> 1 | G27: =IF(A27="","",E27*F27*IF($F$5,1-$E$5,1)) -> 77695.228
A28: =IF(9>$E$4+1,"",9) -> 9 | B28: =IF(A28="","",YEAR('Case Inputs'!$B$6)+A28) -> 2035 | C28: =IF(A28="","",$C$15*(1+$E$3)^A28) -> 98716.387 | D28: =IF(A28="","",IFERROR(INDEX('Discount Rates'!$C:$C,MATCH(TEXT(B28,"0"),'Discount Rates'!$A:$A,0))/100-IF($F$6=TRUE,$E$6,0),0)) -> 0.02738 | E28: =IF(A28="","",C28/((1+D28)^A28)) -> 77412.178 | F28: =IF(A28="","",IF(A28<=$E$4,1,IF(A28=$E$4+1,$B$5,0))) -> 1 | G28: =IF(A28="","",E28*F28*IF($F$5,1-$E$5,1)) -> 77412.178
A29: =IF(10>$E$4+1,"",10) -> 10 | B29: =IF(A29="","",YEAR('Case Inputs'!$B$6)+A29) -> 2036 | C29: =IF(A29="","",$C$15*(1+$E$3)^A29) -> 101776.59 | D29: =IF(A29="","",IFERROR(INDEX('Discount Rates'!$C:$C,MATCH(TEXT(B29,"0"),'Discount Rates'!$A:$A,0))/100-IF($F$6=TRUE,$E$6,0),0)) -> 0.02842 | E29: =IF(A29="","",C29/((1+D29)^A29)) -> 76902.911 | F29: =IF(A29="","",IF(A29<=$E$4,1,IF(A29=$E$4+1,$B$5,0))) -> 1 | G29: =IF(A29="","",E29*F29*IF($F$5,1-$E$5,1)) -> 76902.911
A30: =IF(11>$E$4+1,"",11) -> 11 | B30: =IF(A30="","",YEAR('Case Inputs'!$B$6)+A30) -> 2037 | C30: =IF(A30="","",$C$15*(1+$E$3)^A30) -> 104931.67 | D30: =IF(A30="","",IFERROR(INDEX('Discount Rates'!$C:$C,MATCH(TEXT(B30,"0"),'Discount Rates'!$A:$A,0))/100-IF($F$6=TRUE,$E$6,0),0)) -> 0.02955 | E30: =IF(A30="","",C30/((1+D30)^A30)) -> 76170.132 | F30: =IF(A30="","",IF(A30<=$E$4,1,IF(A30=$E$4+1,$B$5,0))) -> 1 | G30: =IF(A30="","",E30*F30*IF($F$5,1-$E$5,1)) -> 76170.132
A31: =IF(12>$E$4+1,"",12) -> 12 | B31: =IF(A31="","",YEAR('Case Inputs'!$B$6)+A31) -> 2038 | C31: =IF(A31="","",$C$15*(1+$E$3)^A31) -> 108184.55 | D31: =IF(A31="","",IFERROR(INDEX('Discount Rates'!$C:$C,MATCH(TEXT(B31,"0"),'Discount Rates'!$A:$A,0))/100-IF($F$6=TRUE,$E$6,0),0)) -> 0.03063 | E31: =IF(A31="","",C31/((1+D31)^A31)) -> 75323.742 | F31: =IF(A31="","",IF(A31<=$E$4,1,IF(A31=$E$4+1,$B$5,0))) -> 1 | G31: =IF(A31="","",E31*F31*IF($F$5,1-$E$5,1)) -> 75323.742
A32: =IF(13>$E$4+1,"",13) -> 13 | B32: =IF(A32="","",YEAR('Case Inputs'!$B$6)+A32) -> 2039 | C32: =IF(A32="","",$C$15*(1+$E$3)^A32) -> 111538.27 | D32: =IF(A32="","",IFERROR(INDEX('Discount Rates'!$C:$C,MATCH(TEXT(B32,"0"),'Discount Rates'!$A:$A,0))/100-IF($F$6=TRUE,$E$6,0),0)) -> 0.03137 | E32: =IF(A32="","",C32/((1+D32)^A32)) -> 74650.974 | F32: =IF(A32="","",IF(A32<=$E$4,1,IF(A32=$E$4+1,$B$5,0))) -> 1 | G32: =IF(A32="","",E32*F32*IF($F$5,1-$E$5,1)) -> 74650.974
A33: =IF(14>$E$4+1,"",14) -> 14 | B33: =IF(A33="","",YEAR('Case Inputs'!$B$6)+A33) -> 2040 | C33: =IF(A33="","",$C$15*(1+$E$3)^A33) -> 114995.96 | D33: =IF(A33="","",IFERROR(INDEX('Discount Rates'!$C:$C,MATCH(TEXT(B33,"0"),'Discount Rates'!$A:$A,0))/100-IF($F$6=TRUE,$E$6,0),0)) -> 0.03243 | E33: =IF(A33="","",C33/((1+D33)^A33)) -> 73558.685 | F33: =IF(A33="","",IF(A33<=$E$4,1,IF(A33=$E$4+1,$B$5,0))) -> 1 | G33: =IF(A33="","",E33*F33*IF($F$5,1-$E$5,1)) -> 73558.685
A34: =IF(15>$E$4+1,"",15) -> 15 | B34: =IF(A34="","",YEAR('Case Inputs'!$B$6)+A34) -> 2041 | C34: =IF(A34="","",$C$15*(1+$E$3)^A34) -> 118560.83 | D34: =IF(A34="","",IFERROR(INDEX('Discount Rates'!$C:$C,MATCH(TEXT(B34,"0"),'Discount Rates'!$A:$A,0))/100-IF($F$6=TRUE,$E$6,0),0)) -> 0.03297 | E34: =IF(A34="","",C34/((1+D34)^A34)) -> 72882.894 | F34: =IF(A34="","",IF(A34<=$E$4,1,IF(A34=$E$4+1,$B$5,0))) -> 0.29256674 | G34: =IF(A34="","",E34*F34*IF($F$5,1-$E$5,1)) -> 21323.11
A35: =IF(16>$E$4+1,"",16) | B35: =IF(A35="","",YEAR('Case Inputs'!$B$6)+A35) | C35: =IF(A35="","",$C$15*(1+$E$3)^A35) | D35: =IF(A35="","",IFERROR(INDEX('Discount Rates'!$C:$C,MATCH(TEXT(B35,"0"),'Discount Rates'!$A:$A,0))/100-IF($F$6=TRUE,$E$6,0),0)) | E35: =IF(A35="","",C35/((1+D35)^A35)) | F35: =IF(A35="","",IF(A35<=$E$4,1,IF(A35=$E$4+1,$B$5,0))) | G35: =IF(A35="","",E35*F35*IF($F$5,1-$E$5,1))
A36: =IF(17>$E$4+1,"",17) | B36: =IF(A36="","",YEAR('Case Inputs'!$B$6)+A36) | C36: =IF(A36="","",$C$15*(1+$E$3)^A36) | D36: =IF(A36="","",IFERROR(INDEX('Discount Rates'!$C:$C,MATCH(TEXT(B36,"0"),'Discount Rates'!$A:$A,0))/100-IF($F$6=TRUE,$E$6,0),0)) | E36: =IF(A36="","",C36/((1+D36)^A36)) | F36: =IF(A36="","",IF(A36<=$E$4,1,IF(A36=$E$4+1,$B$5,0))) | G36: =IF(A36="","",E36*F36*IF($F$5,1-$E$5,1))
A37: =IF(18>$E$4+1,"",18) | B37: =IF(A37="","",YEAR('Case Inputs'!$B$6)+A37) | C37: =IF(A37="","",$C$15*(1+$E$3)^A37) | D37: =IF(A37="","",IFERROR(INDEX('Discount Rates'!$C:$C,MATCH(TEXT(B37,"0"),'Discount Rates'!$A:$A,0))/100-IF($F$6=TRUE,$E$6,0),0)) | E37: =IF(A37="","",C37/((1+D37)^A37)) | F37: =IF(A37="","",IF(A37<=$E$4,1,IF(A37=$E$4+1,$B$5,0))) | G37: =IF(A37="","",E37*F37*IF($F$5,1-$E$5,1))
A38: =IF(19>$E$4+1,"",19) | B38: =IF(A38="","",YEAR('Case Inputs'!$B$6)+A38) | C38: =IF(A38="","",$C$15*(1+$E$3)^A38) | D38: =IF(A38="","",IFERROR(INDEX('Discount Rates'!$C:$C,MATCH(TEXT(B38,"0"),'Discount Rates'!$A:$A,0))/100-IF($F$6=TRUE,$E$6,0),0)) | E38: =IF(A38="","",C38/((1+D38)^A38)) | F38: =IF(A38="","",IF(A38<=$E$4,1,IF(A38=$E$4+1,$B$5,0))) | G38: =IF(A38="","",E38*F38*IF($F$5,1-$E$5,1))
A39: =IF(20>$E$4+1,"",20) | B39: =IF(A39="","",YEAR('Case Inputs'!$B$6)+A39) | C39: =IF(A39="","",$C$15*(1+$E$3)^A39) | D39: =IF(A39="","",IFERROR(INDEX('Discount Rates'!$C:$C,MATCH(TEXT(B39,"0"),'Discount Rates'!$A:$A,0))/100-IF($F$6=TRUE,$E$6,0),0)) | E39: =IF(A39="","",C39/((1+D39)^A39)) | F39: =IF(A39="","",IF(A39<=$E$4,1,IF(A39=$E$4+1,$B$5,0))) | G39: =IF(A39="","",E39*F39*IF($F$5,1-$E$5,1))
A40: =IF(21>$E$4+1,"",21) | B40: =IF(A40="","",YEAR('Case Inputs'!$B$6)+A40) | C40: =IF(A40="","",$C$15*(1+$E$3)^A40) | D40: =IF(A40="","",IFERROR(INDEX('Discount Rates'!$C:$C,MATCH(TEXT(B40,"0"),'Discount Rates'!$A:$A,0))/100-IF($F$6=TRUE,$E$6,0),0)) | E40: =IF(A40="","",C40/((1+D40)^A40)) | F40: =IF(A40="","",IF(A40<=$E$4,1,IF(A40=$E$4+1,$B$5,0))) | G40: =IF(A40="","",E40*F40*IF($F$5,1-$E$5,1))
A41: =IF(22>$E$4+1,"",22) | B41: =IF(A41="","",YEAR('Case Inputs'!$B$6)+A41) | C41: =IF(A41="","",$C$15*(1+$E$3)^A41) | D41: =IF(A41="","",IFERROR(INDEX('Discount Rates'!$C:$C,MATCH(TEXT(B41,"0"),'Discount Rates'!$A:$A,0))/100-IF($F$6=TRUE,$E$6,0),0)) | E41: =IF(A41="","",C41/((1+D41)^A41)) | F41: =IF(A41="","",IF(A41<=$E$4,1,IF(A41=$E$4+1,$B$5,0))) | G41: =IF(A41="","",E41*F41*IF($F$5,1-$E$5,1))
A42: =IF(23>$E$4+1,"",23) | B42: =IF(A42="","",YEAR('Case Inputs'!$B$6)+A42) | C42: =IF(A42="","",$C$15*(1+$E$3)^A42) | D42: =IF(A42="","",IFERROR(INDEX('Discount Rates'!$C:$C,MATCH(TEXT(B42,"0"),'Discount Rates'!$A:$A,0))/100-IF($F$6=TRUE,$E$6,0),0)) | E42: =IF(A42="","",C42/((1+D42)^A42)) | F42: =IF(A42="","",IF(A42<=$E$4,1,IF(A42=$E$4+1,$B$5,0))) | G42: =IF(A42="","",E42*F42*IF($F$5,1-$E$5,1))
A43: =IF(24>$E$4+1,"",24) | B43: =IF(A43="","",YEAR('Case Inputs'!$B$6)+A43) | C43: =IF(A43="","",$C$15*(1+$E$3)^A43) | D43: =IF(A43="","",IFERROR(INDEX('Discount Rates'!$C:$C,MATCH(TEXT(B43,"0"),'Discount Rates'!$A:$A,0))/100-IF($F$6=TRUE,$E$6,0),0)) | E43: =IF(A43="","",C43/((1+D43)^A43)) | F43: =IF(A43="","",IF(A43<=$E$4,1,IF(A43=$E$4+1,$B$5,0))) | G43: =IF(A43="","",E43*F43*IF($F$5,1-$E$5,1))
A44: =IF(25>$E$4+1,"",25) | B44: =IF(A44="","",YEAR('Case Inputs'!$B$6)+A44) | C44: =IF(A44="","",$C$15*(1+$E$3)^A44) | D44: =IF(A44="","",IFERROR(INDEX('Discount Rates'!$C:$C,MATCH(TEXT(B44,"0"),'Discount Rates'!$A:$A,0))/100-IF($F$6=TRUE,$E$6,0),0)) | E44: =IF(A44="","",C44/((1+D44)^A44)) | F44: =IF(A44="","",IF(A44<=$E$4,1,IF(A44=$E$4+1,$B$5,0))) | G44: =IF(A44="","",E44*F44*IF($F$5,1-$E$5,1))
...

Sheet Base 1 PV Loss To Age
A1: PRESENT VALUE LOSS - BASE 1 TO AGE SCENARIO
A3: Base Earnings: | B3: 141416 | C3: ← INPUT | D3: Growth Rate: | E3: 0.0356 | F3: ← INPUT
A4: Years to Retirement: | B4: ='Case Inputs'!B21 -> 19.037645 | D4: Full Years: | E4: ='Case Inputs'!B22 -> 19
A5: Partial Year: | B5: ='Case Inputs'!B23 -> 0.037645448 | D5: Effective Tax Rate | E5: 0.22 | F5: FALSE
D6: Inflation Rate | E6: =E3 -> 0.0356 | F6: FALSE
A7: PRE-TRIAL LOSSES (Accident to Trial)
A8: Year | B8: Calendar Year | C8: Loss Amount | D8: =IF('Case Inputs'!$B$28="CPI Adjustment","CPI Index",IF('Case Inputs'!$B$28="Custom Rate","","")) | E8: Growth Factor | F8: Proration Factor | G8: Adjusted Loss | H8: Unadjusted Loss
A9: =YEAR('Case Inputs'!$B$5) -> 2021 | B9: =YEAR('Case Inputs'!$B$5) -> 2021 | C9: =$B$3 -> 141416 | D9: =IF('Case Inputs'!$B$28="CPI Adjustment",IFERROR(INDEX('CPI Data'!$F$2:$F$5,MATCH(B9,'CPI Data'!$E$2:$E$5,0)),""),"") | E9: =1 -> 1 | F9: =(DATE(YEAR('Case Inputs'!$B$5),12,31)-'Case Inputs'!$B$5)/365 -> 0.33150685 | G9: =C9*F9*IF($F$5,1-$E$5,1) -> 46880.373 | H9: =C9*F9 -> 46880.373
A10: =IF(YEAR('Case Inputs'!$B$6)-YEAR('Case Inputs'!$B$5)>=2,YEAR('Case Inputs'!$B$5)+1,"") -> 2022 | B10: =IF(A10="","",A10) -> 2022 | C10: =C9*E10 -> 141416 | D10: =IF('Case Inputs'!$B$28="CPI Adjustment",IFERROR(INDEX('CPI Data'!$F$2:$F$5,MATCH(B10,'CPI Data'!$E$2:$E$5,0)),""),"") | E10: =IF('Case Inputs'!$B$28="CPI Adjustment",INDEX('CPI Data'!$F:$F,MATCH(B10,'CPI Data'!$E:$E,0))/INDEX('CPI Data'!$F:$F,MATCH(B9,'CPI Data'!$E:$E,0)),IF('Case Inputs'!$B$28="No Adjustment",1,1+'Case Inputs'!$B$29)) -> 1 | F10: 1 | G10: =C10*F10*IF($F$5,1-$E$5,1) -> 141416 | H10: =C10*F10 -> 141416
A11: =IF(YEAR('Case Inputs'!$B$6)-YEAR('Case Inputs'!$B$5)>=3,YEAR('Case Inputs'!$B$5)+2,"") -> 2023 | B11: =IF(A11="","",A11) -> 2023 | C11: =C10*E11 -> 141416 | D11: =IF('Case Inputs'!$B$28="CPI Adjustment",IFERROR(INDEX('CPI Data'!$F$2:$F$5,MATCH(B11,'CPI Data'!$E$2:$E$5,0)),""),"") | E11: =IF('Case Inputs'!$B$28="CPI Adjustment",INDEX('CPI Data'!$F:$F,MATCH(B11,'CPI Data'!$E:$E,0))/INDEX('CPI Data'!$F:$F,MATCH(B10,'CPI Data'!$E:$E,0)),IF('Case Inputs'!$B$28="No Adjustment",1,1+'Case Inputs'!$B$29)) -> 1 | F11: 1 | G11: =C11*F11*IF($F$5,1-$E$5,1) -> 141416 | H11: =C11*F11 -> 141416
A12: =IF(YEAR('Case Inputs'!$B$6)-YEAR('Case Inputs'!$B$5)>=4,YEAR('Case Inputs'!$B$5)+3,"") -> 2024 | B12: =IF(A12="","",A12) -> 2024 | C12: =IF(A12="","",C11*E12) -> 141416 | D12: =IF(A12="","",IF('Case Inputs'!$B$28="CPI Adjustment",IFERROR(INDEX('CPI Data'!$F$2:$F$10,MATCH(B12,'CPI Data'!$E$2:$E$10,0)),""),"")) | E12: =IF(A12="","",IF('Case Inputs'!$B$28="CPI Adjustment",INDEX('CPI Data'!$F:$F,MATCH(B12,'CPI Data'!$E:$E,0))/INDEX('CPI Data'!$F:$F,MATCH(B11,'CPI Data'!$E:$E,0)),IF('Case Inputs'!$B$28="No Adjustment",1,1+'Case Inputs'!$B$29))) -> 1 | F12: =IF(A12="","",1) -> 1 | G12: =IF(A12="","",C12*F12*IF($F$5,1-$E$5,1)) -> 141416 | H12: =C12*F12 -> 141416
A13: =IF(YEAR('Case Inputs'!$B$6)-YEAR('Case Inputs'!$B$5)>=5,YEAR('Case Inputs'!$B$5)+4,"") -> 2025 | B13: =IF(A13="","",A13) -> 2025 | C13: =IF(A13="","",C12*E13) -> 141416 | D13: =IF(A13="","",IF('Case Inputs'!$B$28="CPI Adjustment",IFERROR(INDEX('CPI Data'!$F$2:$F$10,MATCH(B13,'CPI Data'!$E$2:$E$10,0)),""),"")) | E13: =IF(A13="","",IF('Case Inputs'!$B$28="CPI Adjustment",INDEX('CPI Data'!$F:$F,MATCH(B13,'CPI Data'!$E:$E,0))/INDEX('CPI Data'!$F:$F,MATCH(B12,'CPI Data'!$E:$E,0)),IF('Case Inputs'!$B$28="No Adjustment",1,1+'Case Inputs'!$B$29))) -> 1 | F13: =IF(A13="","",1) -> 1 | G13: =IF(A13="","",C13*F13*IF($F$5,1-$E$5,1)) -> 141416 | H13: =C13*F13 -> 141416
A15: =YEAR('Case Inputs'!$B$6) -> 2026 | B15: =YEAR('Case Inputs'!$B$6) -> 2026 | C15: =IF(A13<>"",C13*E15,IF(A12<>"",C12*E15,IF(A11<>"",C11*E15,IF(A10<>"",C10*E15,C9*E15)))) -> 141416 | D15: =IF('Case Inputs'!$B$28="CPI Adjustment",IFERROR(INDEX('CPI Data'!$F$2:$F$5,MATCH(B15,'CPI Data'!$E$2:$E$5,0)),""),"") | E15: =IF('Case Inputs'!$B$28="CPI Adjustment",INDEX('CPI Data'!$F:$F,MATCH(B15,'CPI Data'!$E:$E,0))/INDEX('CPI Data'!$F:$F,MATCH(IF(A13<>"",B13,IF(A12<>"",B12,IF(A11<>"",B11,IF(A10<>"",B10,B9)))),'CPI Data'!$E:$E,0)),IF('Case Inputs'!$B$28="No Adjustment",1,1+'Case Inputs'!$B$29)) -> 1 | F15: =('Case Inputs'!$B$6-DATE(YEAR('Case Inputs'!$B$6),1,1))/365 -> 0.41369863 | G15: =C15*F15*IF($F$5,1-$E$5,1) -> 58503.605 | H15: =C15*F15 -> 58503.605
A17: PRE-TRIAL SUBTOTAL | G17: =SUM(G9:G15) -> 671047.98 | H17: =SUM(H9:H15) -> 671047.98
A19: POST-TRIAL LOSSES (Trial to Retirement)
A20: =IF(1>$E$4+1,"",1) -> 1 | B20: =IF(A20="","",YEAR('Case Inputs'!$B$6)+A20) -> 2027 | C20: =IF(A20="","",$C$15*(1+$E$3)^A20) -> 146450.41 | D20: =IF(A20="","",IFERROR(INDEX('Discount Rates'!$C:$C,MATCH(TEXT(B20,"0"),'Discount Rates'!$A:$A,0))/100-IF($F$6=TRUE,$E$6,0),0)) -> 0.02301 | E20: =IF(A20="","",C20/((1+D20)^A20)) -> 143156.38 | F20: =IF(A20="","",IF(A20<=$E$4,1,IF(A20=$E$4+1,$B$5,0))) -> 1 | G20: =IF(A20="","",E20*F20*IF($F$5,1-$E$5,1)) -> 143156.38
A21: =IF(2>$E$4+1,"",2) -> 2 | B21: =IF(A21="","",YEAR('Case Inputs'!$B$6)+A21) -> 2028 | C21: =IF(A21="","",$C$15*(1+$E$3)^A21) -> 151664.04 | D21: =IF(A21="","",IFERROR(INDEX('Discount Rates'!$C:$C,MATCH(TEXT(B21,"0"),'Discount Rates'!$A:$A,0))/100-IF($F$6=TRUE,$E$6,0),0)) -> 0.02291 | E21: =IF(A21="","",C21/((1+D21)^A21)) -> 144946.52 | F21: =IF(A21="","",IF(A21<=$E$4,1,IF(A21=$E$4+1,$B$5,0))) -> 1 | G21: =IF(A21="","",E21*F21*IF($F$5,1-$E$5,1)) -> 144946.52
A22: =IF(3>$E$4+1,"",3) -> 3 | B22: =IF(A22="","",YEAR('Case Inputs'!$B$6)+A22) -> 2029 | C22: =IF(A22="","",$C$15*(1+$E$3)^A22) -> 157063.28 | D22: =IF(A22="","",IFERROR(INDEX('Discount Rates'!$C:$C,MATCH(TEXT(B22,"0"),'Discount Rates'!$A:$A,0))/100-IF($F$6=TRUE,$E$6,0),0)) -> 0.02289 | E22: =IF(A22="","",C22/((1+D22)^A22)) -> 146753.3 | F22: =IF(A22="","",IF(A22<=$E$4,1,IF(A22=$E$4+1,$B$5,0))) -> 1 | G22: =IF(A22="","",E22*F22*IF($F$5,1-$E$5,1)) -> 146753.3
A23: =IF(4>$E$4+1,"",4) -> 4 | B23: =IF(A23="","",YEAR('Case Inputs'!$B$6)+A23) -> 2030 | C23: =IF(A23="","",$C$15*(1+$E$3)^A23) -> 162654.74 | D23: =IF(A23="","",IFERROR(INDEX('Discount Rates'!$C:$C,MATCH(TEXT(B23,"0"),'Discount Rates'!$A:$A,0))/100-IF($F$6=TRUE,$E$6,0),0)) -> 0.02346 | E23: =IF(A23="","",C23/((1+D23)^A23)) -> 148246.08 | F23: =IF(A23="","",IF(A23<=$E$4,1,IF(A23=$E$4+1,$B$5,0))) -> 1 | G23: =IF(A23="","",E23*F23*IF($F$5,1-$E$5,1)) -> 148246.08
A24: =IF(5>$E$4+1,"",5) -> 5 | B24: =IF(A24="","",YEAR('Case Inputs'!$B$6)+A24) -> 2031 | C24: =IF(A24="","",$C$15*(1+$E$3)^A24) -> 168445.25 | D24: =IF(A24="","",IFERROR(INDEX('Discount Rates'!$C:$C,MATCH(TEXT(B24,"0"),'Discount Rates'!$A:$A,0))/100-IF($F$6=TRUE,$E$6,0),0)) -> 0.02397 | E24: =IF(A24="","",C24/((1+D24)^A24)) -> 149631.35 | F24: =IF(A24="","",IF(A24<=$E$4,1,IF(A24=$E$4+1,$B$5,0))) -> 1 | G24: =IF(A24="","",E24*F24*IF($F$5,1-$E$5,1)) -> 149631.35
A25: =IF(6>$E$4+1,"",6) -> 6 | B25: =IF(A25="","",YEAR('Case Inputs'!$B$6)+A25) -> 2032 | C25: =IF(A25="","",$C$15*(1+$E$3)^A25) -> 174441.9 | D25: =IF(A25="","",IFERROR(INDEX('Discount Rates'!$C:$C,MATCH(TEXT(B25,"0"),'Discount Rates'!$A:$A,0))/100-IF($F$6=TRUE,$E$6,0),0)) -> 0.02481 | E25: =IF(A25="","",C25/((1+D25)^A25)) -> 150588.11 | F25: =IF(A25="","",IF(A25<=$E$4,1,IF(A25=$E$4+1,$B$5,0))) -> 1 | G25: =IF(A25="","",E25*F25*IF($F$5,1-$E$5,1)) -> 150588.11
A26: =IF(7>$E$4+1,"",7) -> 7 | B26: =IF(A26="","",YEAR('Case Inputs'!$B$6)+A26) -> 2033 | C26: =IF(A26="","",$C$15*(1+$E$3)^A26) -> 180652.03 | D26: =IF(A26="","",IFERROR(INDEX('Discount Rates'!$C:$C,MATCH(TEXT(B26,"0"),'Discount Rates'!$A:$A,0))/100-IF($F$6=TRUE,$E$6,0),0)) -> 0.02581 | E26: =IF(A26="","",C26/((1+D26)^A26)) -> 151138.23 | F26: =IF(A26="","",IF(A26<=$E$4,1,IF(A26=$E$4+1,$B$5,0))) -> 1 | G26: =IF(A26="","",E26*F26*IF($F$5,1-$E$5,1)) -> 151138.23
A27: =IF(8>$E$4+1,"",8) -> 8 | B27: =IF(A27="","",YEAR('Case Inputs'!$B$6)+A27) -> 2034 | C27: =IF(A27="","",$C$15*(1+$E$3)^A27) -> 187083.24 | D27: =IF(A27="","",IFERROR(INDEX('Discount Rates'!$C:$C,MATCH(TEXT(B27,"0"),'Discount Rates'!$A:$A,0))/100-IF($F$6=TRUE,$E$6,0),0)) -> 0.02646 | E27: =IF(A27="","",C27/((1+D27)^A27)) -> 151809.39 | F27: =IF(A27="","",IF(A27<=$E$4,1,IF(A27=$E$4+1,$B$5,0))) -> 1 | G27: =IF(A27="","",E27*F27*IF($F$5,1-$E$5,1)) -> 151809.39
A28: =IF(9>$E$4+1,"",9) -> 9 | B28: =IF(A28="","",YEAR('Case Inputs'!$B$6)+A28) -> 2035 | C28: =IF(A28="","",$C$15*(1+$E$3)^A28) -> 193743.4 | D28: =IF(A28="","",IFERROR(INDEX('Discount Rates'!$C:$C,MATCH(TEXT(B28,"0"),'Discount Rates'!$A:$A,0))/100-IF($F$6=TRUE,$E$6,0),0)) -> 0.02738 | E28: =IF(A28="","",C28/((1+D28)^A28)) -> 151931.2 | F28: =IF(A28="","",IF(A28<=$E$4,1,IF(A28=$E$4+1,$B$5,0))) -> 1 | G28: =IF(A28="","",E28*F28*IF($F$5,1-$E$5,1)) -> 151931.2
A29: =IF(10>$E$4+1,"",10) -> 10 | B29: =IF(A29="","",YEAR('Case Inputs'!$B$6)+A29) -> 2036 | C29: =IF(A29="","",$C$15*(1+$E$3)^A29) -> 200640.67 | D29: =IF(A29="","",IFERROR(INDEX('Discount Rates'!$C:$C,MATCH(TEXT(B29,"0"),'Discount Rates'!$A:$A,0))/100-IF($F$6=TRUE,$E$6,0),0)) -> 0.02842 | E29: =IF(A29="","",C29/((1+D29)^A29)) -> 151605.11 | F29: =IF(A29="","",IF(A29<=$E$4,1,IF(A29=$E$4+1,$B$5,0))) -> 1 | G29: =IF(A29="","",E29*F29*IF($F$5,1-$E$5,1)) -> 151605.11
A30: =IF(11>$E$4+1,"",11) -> 11 | B30: =IF(A30="","",YEAR('Case Inputs'!$B$6)+A30) -> 2037 | C30: =IF(A30="","",$C$15*(1+$E$3)^A30) -> 207783.48 | D30: =IF(A30="","",IFERROR(INDEX('Discount Rates'!$C:$C,MATCH(TEXT(B30,"0"),'Discount Rates'!$A:$A,0))/100-IF($F$6=TRUE,$E$6,0),0)) -> 0.02955 | E30: =IF(A30="","",C30/((1+D30)^A30)) -> 150830.49 | F30: =IF(A30="","",IF(A30<=$E$4,1,IF(A30=$E$4+1,$B$5,0))) -> 1 | G30: =IF(A30="","",E30*F30*IF($F$5,1-$E$5,1)) -> 150830.49
A31: =IF(12>$E$4+1,"",12) -> 12 | B31: =IF(A31="","",YEAR('Case Inputs'!$B$6)+A31) -> 2038 | C31: =IF(A31="","",$C$15*(1+$E$3)^A31) -> 215180.57 | D31: =IF(A31="","",IFERROR(INDEX('Discount Rates'!$C:$C,MATCH(TEXT(B31,"0"),'Discount Rates'!$A:$A,0))/100-IF($F$6=TRUE,$E$6,0),0)) -> 0.03063 | E31: =IF(A31="","",C31/((1+D31)^A31)) -> 149819.96 | F31: =IF(A31="","",IF(A31<=$E$4,1,IF(A31=$E$4+1,$B$5,0))) -> 1 | G31: =IF(A31="","",E31*F31*IF($F$5,1-$E$5,1)) -> 149819.96
