Workbook
Name Age_Initiated: '1st Procedure'!$B:$B
Name Age_Initiated: '2nd'!$B:$B
Name Age_Initiated: '3rd'!$B:$B
Name Age_Initiated: '4th'!$B:$B
Name Age_Initiated: Diagnostic!$B:$B
Name Age_Initiated: Equipment!$B:$B
Name Age_Initiated: Evaluations!$B:$B
Name Age_Initiated: 'Home Maintenance'!$B:$B
Name Age_Initiated: 'Home Services'!$B:$B
Name Age_Initiated: Injections!$B:$B
Name Age_Initiated: Medications!$B:$B
Name Age_Initiated: Prostheses!$B:$B
Name Age_Initiated: 'Routine Care'!$B:$B
Name Age_Initiated: Therapeutic!$B:$B
Name Age_Initiated: Transportation!$B:$B
Name AnnMax: '1st Procedure'!$O:$O
Name AnnMax: '2nd'!$O:$O
Name AnnMax: '3rd'!$O:$O
Name AnnMax: '4th'!$O:$O
Name AnnMax: Diagnostic!$O:$O
Name AnnMax: Equipment!$O:$O
Name AnnMax: Evaluations!$O:$O
Name AnnMax: 'Home Maintenance'!$O:$O
Name AnnMax: 'Home Services'!$O:$O
Name AnnMax: Injections!$O:$O
Name AnnMax: Medications!$O:$O
Name AnnMax: Prostheses!$O:$O
Name AnnMax: 'Routine Care'!$O:$O
Name AnnMax: Therapeutic!$O:$O
Name AnnMax: Transportation!$O:$O
Name AnnMin: '1st Procedure'!$N:$N
Name AnnMin: '2nd'!$N:$N
Name AnnMin: '3rd'!$N:$N
Name AnnMin: '4th'!$N:$N
Name AnnMin: Diagnostic!$N:$N
Name AnnMin: Equipment!$N:$N
Name AnnMin: Evaluations!$N:$N
Name AnnMin: 'Home Maintenance'!$N:$N
Name AnnMin: 'Home Services'!$N:$N
Name AnnMin: Injections!$N:$N
Name AnnMin: Medications!$N:$N
Name AnnMin: Prostheses!$N:$N
Name AnnMin: 'Routine Care'!$N:$N
Name AnnMin: Therapeutic!$N:$N
Name AnnMin: Transportation!$N:$N
Name Duration: '1st Procedure'!$D:$D
Name Duration: '2nd'!$D:$D
Name Duration: '3rd'!$D:$D
Name Duration: '4th'!$D:$D
Name Duration: Diagnostic!$D:$D
Name Duration: Equipment!$D:$D
Name Duration: Evaluations!$D:$D
Name Duration: 'Home Maintenance'!$D:$D
Name Duration: 'Home Services'!$D:$D
Name Duration: Injections!$D:$D
Name Duration: Medications!$D:$D
Name Duration: Prostheses!$D:$D
Name Duration: 'Routine Care'!$D:$D
Name Duration: Transportation!$D:$D
Name durations: 'Drop Downs'!$W$12:$W$16

Sheet Master Data
A1: Today's Date: | B1: =TODAY() -> 46129
A2: Name:
A3: Date of Birth: | U3: Column1 | V3: Column2
A4: Sex: | U4: Los Angeles | V4: 2
A5: Ethnicity: | B5: Only | U5: San Diego | V5: 3
A6: Age: | B6: =ROUND((B1-B3)/365.25,1) -> 126.3 | U6: San Francisco | V6: 4
A7: Life Expectancy: | B7: =B8+B6 -> 136.3 | U7: Palo Alto | V7: 5
A8: Years Remaining | B8: 10
A9: Combined Demographic: | B9: =CONCATENATE(Race," ",Sex) -> Only
A10: L.E. Table #: | B10: =VLOOKUP(B9,'Drop Downs'!S11:T21,2,FALSE) -> #N/A
A13: Title | B13: =IF(Sex="Male","Mr. ","Ms. ") -> Ms.
A14: Surname | B14: =RIGHT(B2,LEN(B2)-FIND(" ",B2)) -> #VALUE!
A18: LUNG-RELATED
A19: Location: | B19: Los Angeles

Sheet 1st Procedure
A1: PROCEDURES
A2: Description: | B2: Age Initiated: | C2: Through Age: | D2: Duration (Years): | E2: Min Cost of Visit: | F2: Max Cost of Visit: | G2: Cost: | H2: Freq Min: | I2: Freq Max: | J2: Time Period Min: | K2: Time Period Max: | L2: Time Value: | M2: Frequency: | N2: Annual Cost Min: | O2: Annual Cost Max: | P2: Annual Cost: | Q2: One-Time Cost Min: | R2: One-Time Cost Max: | S2: One-Time Cost: | U2: Durations? | AA2: Annualized full frequency | AB2: Lifetime full frequency | AC2: Non-lifetime duration | AD2: Non-lifetime frequency | AE2: Non-litime time period
A3: Double Lung Transplant | B3: ='Master Data'!$B$6 -> 126.3 | C3: ='Master Data'!$B$7 -> 136.3 | D3: =ROUND(C3-B3,1) -> 10 | E3: {=IF( $A3="Single Lung Transplant", _xlfn.XLOOKUP(1,'Cost Data Sheet'!$A$2:$A$1003,'Cost Data Sheet'!$F$2:$F$1003), IF( $A3="Double Lung Transplant", _xlfn.XLOOKUP(2,'Cost Data Sheet'!$A$2:$A$1003,'Cost Data Sheet'!$F$2:$F$1003), SUMPRODUCT( ('Service to CPT Map'!$A$2:$A$1017=$A3)* ('Service to CPT Map'!$B$2:$B$1017="Low")* ('Service to CPT Map'!$D$2:$D$1017="Medical")* IFERROR( _xlfn.XLOOKUP( 'Service to CPT Map'!$C$2:$C$1017, 'Cost Data Sheet'!$A$2:$A$1003, CHOOSE( MATCH('Master Data'!$B$19, {"Los Angeles","San Diego","San Francisco","Palo Alto"},0), 'Cost Data Sheet'!$B$2:$B$1003, 'Cost Data Sheet'!$C$2:$C$1003, 'Cost Data Sheet'!$D$2:$D$1003, 'Cost Data Sheet'!$E$2:$E$1003 ) ), 0 ) ) + IF( COUNTIFS( 'Service to CPT Map'!$A$2:$A$1017,$A3, 'Service to CPT Map'!$B$2:$B$1017,"Low", 'Service to CPT Map'!$D$2:$D$1017,"Anesthesia" )>0, SUMPRODUCT( ('Service to CPT Map'!$A$2:$A$1017=$A3)* ('Service to CPT Map'!$B$2:$B$1017="Low")* ('Service to CPT Map'!$D$2:$D$1017="Anesthesia")* IFERROR( _xlfn.XLOOKUP( 'Service to CPT Map'!$C$2:$C$1017, 'Cost Data Sheet'!$A$2:$A$1003, CHOOSE( MATCH('Master Data'!$B$19, {"Los Angeles","San Diego","San Francisco","Palo Alto"},0), 'Cost Data Sheet'!$B$2:$B$1003, 'Cost Data Sheet'!$C$2:$C$1003, 'Cost Data Sheet'!$D$2:$D$1003, 'Cost Data Sheet'!$E$2:$E$1003 ) ), 0 ) ), SUMPRODUCT( ('Service to CPT Map'!$A$2:$A$1017=$A3)* ('Service to CPT Map'!$B$2:$B$1017="Low")* ('Service to CPT Map'!$D$2:$D$1017="Medical - Sedation")* IFERROR( _xlfn.XLOOKUP( 'Service to CPT Map'!$C$2:$C$1017, 'Cost Data Sheet'!$A$2:$A$1003, CHOOSE( MATCH('Master Data'!$B$19, {"Los Angeles","San Diego","San Francisco","Palo Alto"},0), 'Cost Data Sheet'!$B$2:$B$1003, 'Cost Data Sheet'!$C$2:$C$1003, 'Cost Data Sheet'!$D$2:$D$1003, 'Cost Data Sheet'!$E$2:$E$1003 ) ), 0 ) ) ) + MIN( SUMPRODUCT( ('Service to CPT Map'!$A$2:$A$1017=$A3)* ('Service to CPT Map'!$B$2:$B$1017="Low")* ('Service to CPT Map'!$D$2:$D$1017="ASC")* IFERROR( _xlfn.XLOOKUP( 'Service to CPT Map'!$C$2:$C$1017, 'Cost Data Sheet'!$A$2:$A$1003, CHOOSE( MATCH('Master Data'!$B$19, {"Los Angeles","San Diego","San Francisco","Palo Alto"},0), 'Cost Data Sheet'!$B$2:$B$1003, 'Cost Data Sheet'!$C$2:$C$1003, 'Cost Data Sheet'!$D$2:$D$1003, 'Cost Data Sheet'!$E$2:$E$1003 ) ), 0 ) ), SUMPRODUCT( ('Service to CPT Map'!$A$2:$A$1017=$A3)* ('Service to CPT Map'!$B$2:$B$1017="Low")* ('Service to CPT Map'!$D$2:$D$1017="Outpatient")* IFERROR( _xlfn.XLOOKUP( 'Service to CPT Map'!$C$2:$C$1017, 'Cost Data Sheet'!$A$2:$A$1003, CHOOSE( MATCH('Master Data'!$B$19, {"Los Angeles","San Diego","San Francisco","Palo Alto"},0), 'Cost Data Sheet'!$B$2:$B$1003, 'Cost Data Sheet'!$C$2:$C$1003, 'Cost Data Sheet'!$D$2:$D$1003, 'Cost Data Sheet'!$E$2:$E$1003 ) ), 0 ) ) ) ) )} -> 2346500 | F3: {=IF( OR($A3="Single Lung Transplant",$A3="Double Lung Transplant"), E3, SUMPRODUCT( ('Service to CPT Map'!$A$2:$A$1017=$A3)* ('Service to CPT Map'!$B$2:$B$1017="High")* ('Service to CPT Map'!$D$2:$D$1017="Medical")* IFERROR( _xlfn.XLOOKUP( 'Service to CPT Map'!$C$2:$C$1017, 'Cost Data Sheet'!$A$2:$A$1003, CHOOSE( MATCH('Master Data'!$B$19, {"Los Angeles","San Diego","San Francisco","Palo Alto"},0), 'Cost Data Sheet'!$B$2:$B$1003, 'Cost Data Sheet'!$C$2:$C$1003, 'Cost Data Sheet'!$D$2:$D$1003, 'Cost Data Sheet'!$E$2:$E$1003 ) ), 0 ) ) + IF( COUNTIFS( 'Service to CPT Map'!$A$2:$A$1017,$A3, 'Service to CPT Map'!$B$2:$B$1017,"High", 'Service to CPT Map'!$D$2:$D$1017,"Anesthesia" )>0, SUMPRODUCT( ('Service to CPT Map'!$A$2:$A$1017=$A3)* ('Service to CPT Map'!$B$2:$B$1017="High")* ('Service to CPT Map'!$D$2:$D$1017="Anesthesia")* IFERROR( _xlfn.XLOOKUP( 'Service to CPT Map'!$C$2:$C$1017, 'Cost Data Sheet'!$A$2:$A$1003, CHOOSE( MATCH('Master Data'!$B$19, {"Los Angeles","San Diego","San Francisco","Palo Alto"},0), 'Cost Data Sheet'!$B$2:$B$1003, 'Cost Data Sheet'!$C$2:$C$1003, 'Cost Data Sheet'!$D$2:$D$1003, 'Cost Data Sheet'!$E$2:$E$1003 ) ), 0 ) ), SUMPRODUCT( ('Service to CPT Map'!$A$2:$A$1017=$A3)* ('Service to CPT Map'!$B$2:$B$1017="High")* ('Service to CPT Map'!$D$2:$D$1017="Medical - Sedation")* IFERROR( _xlfn.XLOOKUP( 'Service to CPT Map'!$C$2:$C$1017, 'Cost Data Sheet'!$A$2:$A$1003, CHOOSE( MATCH('Master Data'!$B$19, {"Los Angeles","San Diego","San Francisco","Palo Alto"},0), 'Cost Data Sheet'!$B$2:$B$1003, 'Cost Data Sheet'!$C$2:$C$1003, 'Cost Data Sheet'!$D$2:$D$1003, 'Cost Data Sheet'!$E$2:$E$1003 ) ), 0 ) ) ) + MAX( SUMPRODUCT( ('Service to CPT Map'!$A$2:$A$1017=$A3)* ('Service to CPT Map'!$B$2:$B$1017="High")* ('Service to CPT Map'!$D$2:$D$1017="ASC")* IFERROR( _xlfn.XLOOKUP( 'Service to CPT Map'!$C$2:$C$1017, 'Cost Data Sheet'!$A$2:$A$1003, CHOOSE( MATCH('Master Data'!$B$19, {"Los Angeles","San Diego","San Francisco","Palo Alto"},0), 'Cost Data Sheet'!$B$2:$B$1003, 'Cost Data Sheet'!$C$2:$C$1003, 'Cost Data Sheet'!$D$2:$D$1003, 'Cost Data Sheet'!$E$2:$E$1003 ) ), 0 ) ), SUMPRODUCT( ('Service to CPT Map'!$A$2:$A$1017=$A3)* ('Service to CPT Map'!$B$2:$B$1017="High")* ('Service to CPT Map'!$D$2:$D$1017="Outpatient")* IFERROR( _xlfn.XLOOKUP( 'Service to CPT Map'!$C$2:$C$1017, 'Cost Data Sheet'!$A$2:$A$1003, CHOOSE( MATCH('Master Data'!$B$19, {"Los Angeles","San Diego","San Francisco","Palo Alto"},0), 'Cost Data Sheet'!$B$2:$B$1003, 'Cost Data Sheet'!$C$2:$C$1003, 'Cost Data Sheet'!$D$2:$D$1003, 'Cost Data Sheet'!$E$2:$E$1003 ) ), 0 ) ) ) )} -> 2346500 | G3: =IF(E3<F3,CONCATENATE(TEXT(E3,"$#,##0.00"),CHAR(10)," - ",CHAR(10),TEXT(F3,"$#,##0.00")),TEXT(E3,"$#,##0.00")) -> $2,346,500.00 | H3: 1 | L3: =IF(LEN(K3)=0,IF(LEN(J3)=0,"lifetime",IF(J3=1,"year","years")),"years") -> lifetime | M3: =IF(L3="lifetime", IF(I3<>"", H3 & "-" & I3 & "x/lifetime", H3 & "x/lifetime"), IF(D3='Master Data'!$B$8, AD3 & AE3, AD3 & AE3 & AC3)) -> 1x/lifetime | N3: =ROUND(IF(OR(EXACT(TimeValue,"years"),EXACT(TimeValue,"year")),IF(OR(MinTimePeriod>0,MaxTimePeriod>0),MinFreq*MinCost/(IF(MaxTimePeriod>0,MaxTimePeriod,MinTimePeriod)),0),IF(EXACT(TimeValue,"lifetime"),0,IF(OR(EXACT(TimeValue,"month"),EXACT(TimeValue,"months")),IF(OR(MinTimePeriod>0,MaxTimePeriod>0),MinFreq*MinCost/(IF(MaxTimePeriod>0,MaxTimePeriod/12,MinTimePeriod/12)),0),IF(OR(EXACT(TimeValue,"week"),EXACT(TimeValue,"weeks")),IF(OR(MinTimePeriod>0,MaxTimePeriod>0),MinFreq*MinCost/(IF(MaxTimePeriod>0,MaxTimePeriod/52,MinTimePeriod/52)),0),IF(OR(EXACT(TimeValue,"day"),EXACT(TimeValue,"days")),IF(OR(MinTimePeriod>0,MaxTimePeriod>0),MinFreq*MinCost/(IF(MaxTimePeriod>0,MaxTimePeriod/365,MinTimePeriod/365))),"invalidinput"))))),2) -> 0 | O3: =ROUND(IF(TimeValue="lifetime",0,IF(OR(EXACT(TimeValue,"years"),EXACT(TimeValue,"year")),IF(OR(MinTimePeriod>0,MaxTimePeriod>0),(IF(MaxFreq>0,MaxFreq,MinFreq))*MaxCost/MinTimePeriod),IF(OR(EXACT(TimeValue,"month"),EXACT(TimeValue,"months")),IF(OR(MinTimePeriod>0,MaxTimePeriod>0),(IF(MaxFreq>0,MaxFreq,MinFreq))*MaxCost/(MinTimePeriod/12),0),IF(OR(EXACT(TimeValue,"week"),EXACT(TimeValue,"weeks")),IF(OR(MinTimePeriod>0,MaxTimePeriod>0),IF(MaxFreq>0,MaxFreq,MinFreq))*MaxCost/(MinTimePeriod/52),IF(OR(EXACT(TimeValue,"day"),EXACT(TimeValue,"days")),IF(OR(MinTimePeriod>0,MaxTimePeriod>0),IF(MaxFreq>0,MaxFreq,MinFreq))*MaxCost/(MinTimePeriod/365),"invalidinput"))))),2) -> 0 | P3: =IF(N3<O3,CONCATENATE(TEXT(N3,"$#,###.00"),CHAR(10)," - ",CHAR(10),TEXT(O3,"$#,####.00")),TEXT(N3,"$0.00")) -> $0.00 | Q3: =ROUND(IF(TimeValue="lifetime",MinCost*MinFreq,0),2) -> 2346500 | R3: =ROUND(IF(AND(TimeValue="lifetime",MaxFreq<1),MinFreq*MaxCost,IF(AND(TimeValue="lifetime",MaxFreq>=1),MaxFreq*MaxCost,0)),2) -> 2346500 | S3: =IF(Q3<R3,CONCATENATE(TEXT(Q3,"$#,##0.00"),CHAR(10)," - ",CHAR(10),TEXT(R3,"$#,##0.00")),TEXT(Q3,"$#,##0.00")) -> $2,346,500.00 | U3: {=IF(AND(ROUND(Table14[Duration (Years):],1)='Master Data'!$B$8),"same","different")} -> different | V3: Link to copy/paste table here | AA3: =IF(L3="lifetime", "one-time cost", IF(D3='Master Data'!$B$8, AD3 & AE3, AD3 & AE3 & AC3)) -> one-time cost | AB3: =IF(L3="lifetime", IF(I3<>"", H3 & "-" & I3 & "x/lifetime", H3 & "x/lifetime"), "ongoing cost") -> 1x/lifetime | AC3: =IF(Table14[[#This Row],[Duration (Years):]]<>'Master Data'!$B$8,CONCATENATE(",",CHAR(10),"for ",Table14[[#This Row],[Duration (Years):]]," years"),"lifelong") -> lifelong | AD3: =IF(L3="lifetime", "one-time cost", IF(I3<>"", H3 & "-" & I3 & "x/", H3 & "x/")) -> one-time cost | AE3: =IF(L3="lifetime", "one-time cost", IF(K3<>"", J3 & "-" & K3 & " " & L3, IF(J3>1, J3 & " " & L3, L3))) -> one-time cost
A4: Flexible Bronchoscopy with Transbronchial Biopsy or "Cryo Biopsy" | B4: ='Master Data'!$B$6 -> 126.3 | C4: ='Master Data'!$B$7 -> 136.3 | D4: =ROUND(C4-B4,1) -> 10 | E4: {=IF( $A4="Single Lung Transplant", _xlfn.XLOOKUP(1,'Cost Data Sheet'!$A$2:$A$1003,'Cost Data Sheet'!$F$2:$F$1003), IF( $A4="Double Lung Transplant", _xlfn.XLOOKUP(2,'Cost Data Sheet'!$A$2:$A$1003,'Cost Data Sheet'!$F$2:$F$1003), SUMPRODUCT( ('Service to CPT Map'!$A$2:$A$1017=$A4)* ('Service to CPT Map'!$B$2:$B$1017="Low")* ('Service to CPT Map'!$D$2:$D$1017="Medical")* IFERROR( _xlfn.XLOOKUP( 'Service to CPT Map'!$C$2:$C$1017, 'Cost Data Sheet'!$A$2:$A$1003, CHOOSE( MATCH('Master Data'!$B$19, {"Los Angeles","San Diego","San Francisco","Palo Alto"},0), 'Cost Data Sheet'!$B$2:$B$1003, 'Cost Data Sheet'!$C$2:$C$1003, 'Cost Data Sheet'!$D$2:$D$1003, 'Cost Data Sheet'!$E$2:$E$1003 ) ), 0 ) ) + IF( COUNTIFS( 'Service to CPT Map'!$A$2:$A$1017,$A4, 'Service to CPT Map'!$B$2:$B$1017,"Low", 'Service to CPT Map'!$D$2:$D$1017,"Anesthesia" )>0, SUMPRODUCT( ('Service to CPT Map'!$A$2:$A$1017=$A4)* ('Service to CPT Map'!$B$2:$B$1017="Low")* ('Service to CPT Map'!$D$2:$D$1017="Anesthesia")* IFERROR( _xlfn.XLOOKUP( 'Service to CPT Map'!$C$2:$C$1017, 'Cost Data Sheet'!$A$2:$A$1003, CHOOSE( MATCH('Master Data'!$B$19, {"Los Angeles","San Diego","San Francisco","Palo Alto"},0), 'Cost Data Sheet'!$B$2:$B$1003, 'Cost Data Sheet'!$C$2:$C$1003, 'Cost Data Sheet'!$D$2:$D$1003, 'Cost Data Sheet'!$E$2:$E$1003 ) ), 0 ) ), SUMPRODUCT( ('Service to CPT Map'!$A$2:$A$1017=$A4)* ('Service to CPT Map'!$B$2:$B$1017="Low")* ('Service to CPT Map'!$D$2:$D$1017="Medical - Sedation")* IFERROR( _xlfn.XLOOKUP( 'Service to CPT Map'!$C$2:$C$1017, 'Cost Data Sheet'!$A$2:$A$1003, CHOOSE( MATCH('Master Data'!$B$19, {"Los Angeles","San Diego","San Francisco","Palo Alto"},0), 'Cost Data Sheet'!$B$2:$B$1003, 'Cost Data Sheet'!$C$2:$C$1003, 'Cost Data Sheet'!$D$2:$D$1003, 'Cost Data Sheet'!$E$2:$E$1003 ) ), 0 ) ) ) + MIN( SUMPRODUCT( ('Service to CPT Map'!$A$2:$A$1017=$A4)* ('Service to CPT Map'!$B$2:$B$1017="Low")* ('Service to CPT Map'!$D$2:$D$1017="ASC")* IFERROR( _xlfn.XLOOKUP( 'Service to CPT Map'!$C$2:$C$1017, 'Cost Data Sheet'!$A$2:$A$1003, CHOOSE( MATCH('Master Data'!$B$19, {"Los Angeles","San Diego","San Francisco","Palo Alto"},0), 'Cost Data Sheet'!$B$2:$B$1003, 'Cost Data Sheet'!$C$2:$C$1003, 'Cost Data Sheet'!$D$2:$D$1003, 'Cost Data Sheet'!$E$2:$E$1003 ) ), 0 ) ), SUMPRODUCT( ('Service to CPT Map'!$A$2:$A$1017=$A4)* ('Service to CPT Map'!$B$2:$B$1017="Low")* ('Service to CPT Map'!$D$2:$D$1017="Outpatient")* IFERROR( _xlfn.XLOOKUP( 'Service to CPT Map'!$C$2:$C$1017, 'Cost Data Sheet'!$A$2:$A$1003, CHOOSE( MATCH('Master Data'!$B$19, {"Los Angeles","San Diego","San Francisco","Palo Alto"},0), 'Cost Data Sheet'!$B$2:$B$1003, 'Cost Data Sheet'!$C$2:$C$1003, 'Cost Data Sheet'!$D$2:$D$1003, 'Cost Data Sheet'!$E$2:$E$1003 ) ), 0 ) ) ) ) )} -> 16863 | F4: {=IF( OR($A4="Single Lung Transplant",$A4="Double Lung Transplant"), E4, SUMPRODUCT( ('Service to CPT Map'!$A$2:$A$1017=$A4)* ('Service to CPT Map'!$B$2:$B$1017="High")* ('Service to CPT Map'!$D$2:$D$1017="Medical")* IFERROR( _xlfn.XLOOKUP( 'Service to CPT Map'!$C$2:$C$1017, 'Cost Data Sheet'!$A$2:$A$1003, CHOOSE( MATCH('Master Data'!$B$19, {"Los Angeles","San Diego","San Francisco","Palo Alto"},0), 'Cost Data Sheet'!$B$2:$B$1003, 'Cost Data Sheet'!$C$2:$C$1003, 'Cost Data Sheet'!$D$2:$D$1003, 'Cost Data Sheet'!$E$2:$E$1003 ) ), 0 ) ) + IF( COUNTIFS( 'Service to CPT Map'!$A$2:$A$1017,$A4, 'Service to CPT Map'!$B$2:$B$1017,"High", 'Service to CPT Map'!$D$2:$D$1017,"Anesthesia" )>0, SUMPRODUCT( ('Service to CPT Map'!$A$2:$A$1017=$A4)* ('Service to CPT Map'!$B$2:$B$1017="High")* ('Service to CPT Map'!$D$2:$D$1017="Anesthesia")* IFERROR( _xlfn.XLOOKUP( 'Service to CPT Map'!$C$2:$C$1017, 'Cost Data Sheet'!$A$2:$A$1003, CHOOSE( MATCH('Master Data'!$B$19, {"Los Angeles","San Diego","San Francisco","Palo Alto"},0), 'Cost Data Sheet'!$B$2:$B$1003, 'Cost Data Sheet'!$C$2:$C$1003, 'Cost Data Sheet'!$D$2:$D$1003, 'Cost Data Sheet'!$E$2:$E$1003 ) ), 0 ) ), SUMPRODUCT( ('Service to CPT Map'!$A$2:$A$1017=$A4)* ('Service to CPT Map'!$B$2:$B$1017="High")* ('Service to CPT Map'!$D$2:$D$1017="Medical - Sedation")* IFERROR( _xlfn.XLOOKUP( 'Service to CPT Map'!$C$2:$C$1017, 'Cost Data Sheet'!$A$2:$A$1003, CHOOSE( MATCH('Master Data'!$B$19, {"Los Angeles","San Diego","San Francisco","Palo Alto"},0), 'Cost Data Sheet'!$B$2:$B$1003, 'Cost Data Sheet'!$C$2:$C$1003, 'Cost Data Sheet'!$D$2:$D$1003, 'Cost Data Sheet'!$E$2:$E$1003 ) ), 0 ) ) ) + MAX( SUMPRODUCT( ('Service to CPT Map'!$A$2:$A$1017=$A4)* ('Service to CPT Map'!$B$2:$B$1017="High")* ('Service to CPT Map'!$D$2:$D$1017="ASC")* IFERROR( _xlfn.XLOOKUP( 'Service to CPT Map'!$C$2:$C$1017, 'Cost Data Sheet'!$A$2:$A$1003, CHOOSE( MATCH('Master Data'!$B$19, {"Los Angeles","San Diego","San Francisco","Palo Alto"},0), 'Cost Data Sheet'!$B$2:$B$1003, 'Cost Data Sheet'!$C$2:$C$1003, 'Cost Data Sheet'!$D$2:$D$1003, 'Cost Data Sheet'!$E$2:$E$1003 ) ), 0 ) ), SUMPRODUCT( ('Service to CPT Map'!$A$2:$A$1017=$A4)* ('Service to CPT Map'!$B$2:$B$1017="High")* ('Service to CPT Map'!$D$2:$D$1017="Outpatient")* IFERROR( _xlfn.XLOOKUP( 'Service to CPT Map'!$C$2:$C$1017, 'Cost Data Sheet'!$A$2:$A$1003, CHOOSE( MATCH('Master Data'!$B$19, {"Los Angeles","San Diego","San Francisco","Palo Alto"},0), 'Cost Data Sheet'!$B$2:$B$1003, 'Cost Data Sheet'!$C$2:$C$1003, 'Cost Data Sheet'!$D$2:$D$1003, 'Cost Data Sheet'!$E$2:$E$1003 ) ), 0 ) ) ) )} -> 22139 | G4: =IF(E4<F4,CONCATENATE(TEXT(E4,"$#,##0.00"),CHAR(10)," - ",CHAR(10),TEXT(F4,"$#,##0.00")),TEXT(E4,"$#,##0.00")) -> $16,863.00 - $22,139.00 | H4: 5 | L4: =IF(LEN(K4)=0,IF(LEN(J4)=0,"lifetime",IF(J4=1,"year","years")),"years") -> lifetime | M4: =IF(L4="lifetime", IF(I4<>"", H4 & "-" & I4 & "x/lifetime", H4 & "x/lifetime"), IF(D4='Master Data'!$B$8, AD4 & AE4, AD4 & AE4 & AC4)) -> 5x/lifetime | N4: =ROUND(IF(OR(EXACT(TimeValue,"years"),EXACT(TimeValue,"year")),IF(OR(MinTimePeriod>0,MaxTimePeriod>0),MinFreq*MinCost/(IF(MaxTimePeriod>0,MaxTimePeriod,MinTimePeriod)),0),IF(EXACT(TimeValue,"lifetime"),0,IF(OR(EXACT(TimeValue,"month"),EXACT(TimeValue,"months")),IF(OR(MinTimePeriod>0,MaxTimePeriod>0),MinFreq*MinCost/(IF(MaxTimePeriod>0,MaxTimePeriod/12,MinTimePeriod/12)),0),IF(OR(EXACT(TimeValue,"week"),EXACT(TimeValue,"weeks")),IF(OR(MinTimePeriod>0,MaxTimePeriod>0),MinFreq*MinCost/(IF(MaxTimePeriod>0,MaxTimePeriod/52,MinTimePeriod/52)),0),IF(OR(EXACT(TimeValue,"day"),EXACT(TimeValue,"days")),IF(OR(MinTimePeriod>0,MaxTimePeriod>0),MinFreq*MinCost/(IF(MaxTimePeriod>0,MaxTimePeriod/365,MinTimePeriod/365))),"invalidinput"))))),2) -> 0 | O4: =ROUND(IF(TimeValue="lifetime",0,IF(OR(EXACT(TimeValue,"years"),EXACT(TimeValue,"year")),IF(OR(MinTimePeriod>0,MaxTimePeriod>0),(IF(MaxFreq>0,MaxFreq,MinFreq))*MaxCost/MinTimePeriod),IF(OR(EXACT(TimeValue,"month"),EXACT(TimeValue,"months")),IF(OR(MinTimePeriod>0,MaxTimePeriod>0),(IF(MaxFreq>0,MaxFreq,MinFreq))*MaxCost/(MinTimePeriod/12),0),IF(OR(EXACT(TimeValue,"week"),EXACT(TimeValue,"weeks")),IF(OR(MinTimePeriod>0,MaxTimePeriod>0),IF(MaxFreq>0,MaxFreq,MinFreq))*MaxCost/(MinTimePeriod/52),IF(OR(EXACT(TimeValue,"day"),EXACT(TimeValue,"days")),IF(OR(MinTimePeriod>0,MaxTimePeriod>0),IF(MaxFreq>0,MaxFreq,MinFreq))*MaxCost/(MinTimePeriod/365),"invalidinput"))))),2) -> 0 | P4: =IF(N4<O4,CONCATENATE(TEXT(N4,"$#,###.00"),CHAR(10)," - ",CHAR(10),TEXT(O4,"$#,####.00")),TEXT(N4,"$0.00")) -> $0.00 | Q4: =ROUND(IF(TimeValue="lifetime",MinCost*MinFreq,0),2) -> 84315 | R4: =ROUND(IF(AND(TimeValue="lifetime",MaxFreq<1),MinFreq*MaxCost,IF(AND(TimeValue="lifetime",MaxFreq>=1),MaxFreq*MaxCost,0)),2) -> 110695 | S4: =IF(Q4<R4,CONCATENATE(TEXT(Q4,"$#,##0.00"),CHAR(10)," - ",CHAR(10),TEXT(R4,"$#,##0.00")),TEXT(Q4,"$#,##0.00")) -> $84,315.00 - $110,695.00 | AA4: =IF(L4="lifetime", "one-time cost", IF(D4='Master Data'!$B$8, AD4 & AE4, AD4 & AE4 & AC4)) -> one-time cost | AB4: =IF(L4="lifetime", IF(I4<>"", H4 & "-" & I4 & "x/lifetime", H4 & "x/lifetime"), "ongoing cost") -> 5x/lifetime | AC4: =IF(Table14[[#This Row],[Duration (Years):]]<>'Master Data'!$B$8,CONCATENATE(",",CHAR(10),"for ",Table14[[#This Row],[Duration (Years):]]," years"),"lifelong") -> lifelong | AD4: =IF(L4="lifetime", "one-time cost", IF(I4<>"", H4 & "-" & I4 & "x/", H4 & "x/")) -> one-time cost | AE4: =IF(L4="lifetime", "one-time cost", IF(K4<>"", J4 & "-" & K4 & " " & L4, IF(J4>1, J4 & " " & L4, L4))) -> one-time cost
A5: Mohs Procedure | B5: ='Master Data'!$B$6 -> 126.3 | C5: ='Master Data'!$B$7 -> 136.3 | D5: =ROUND(C5-B5,1) -> 10 | E5: {=IF( $A5="Single Lung Transplant", _xlfn.XLOOKUP(1,'Cost Data Sheet'!$A$2:$A$1003,'Cost Data Sheet'!$F$2:$F$1003), IF( $A5="Double Lung Transplant", _xlfn.XLOOKUP(2,'Cost Data Sheet'!$A$2:$A$1003,'Cost Data Sheet'!$F$2:$F$1003), SUMPRODUCT( ('Service to CPT Map'!$A$2:$A$1017=$A5)* ('Service to CPT Map'!$B$2:$B$1017="Low")* ('Service to CPT Map'!$D$2:$D$1017="Medical")* IFERROR( _xlfn.XLOOKUP( 'Service to CPT Map'!$C$2:$C$1017, 'Cost Data Sheet'!$A$2:$A$1003, CHOOSE( MATCH('Master Data'!$B$19, {"Los Angeles","San Diego","San Francisco","Palo Alto"},0), 'Cost Data Sheet'!$B$2:$B$1003, 'Cost Data Sheet'!$C$2:$C$1003, 'Cost Data Sheet'!$D$2:$D$1003, 'Cost Data Sheet'!$E$2:$E$1003 ) ), 0 ) ) + IF( COUNTIFS( 'Service to CPT Map'!$A$2:$A$1017,$A5, 'Service to CPT Map'!$B$2:$B$1017,"Low", 'Service to CPT Map'!$D$2:$D$1017,"Anesthesia" )>0, SUMPRODUCT( ('Service to CPT Map'!$A$2:$A$1017=$A5)* ('Service to CPT Map'!$B$2:$B$1017="Low")* ('Service to CPT Map'!$D$2:$D$1017="Anesthesia")* IFERROR( _xlfn.XLOOKUP( 'Service to CPT Map'!$C$2:$C$1017, 'Cost Data Sheet'!$A$2:$A$1003, CHOOSE( MATCH('Master Data'!$B$19, {"Los Angeles","San Diego","San Francisco","Palo Alto"},0), 'Cost Data Sheet'!$B$2:$B$1003, 'Cost Data Sheet'!$C$2:$C$1003, 'Cost Data Sheet'!$D$2:$D$1003, 'Cost Data Sheet'!$E$2:$E$1003 ) ), 0 ) ), SUMPRODUCT( ('Service to CPT Map'!$A$2:$A$1017=$A5)* ('Service to CPT Map'!$B$2:$B$1017="Low")* ('Service to CPT Map'!$D$2:$D$1017="Medical - Sedation")* IFERROR( _xlfn.XLOOKUP( 'Service to CPT Map'!$C$2:$C$1017, 'Cost Data Sheet'!$A$2:$A$1003, CHOOSE( MATCH('Master Data'!$B$19, {"Los Angeles","San Diego","San Francisco","Palo Alto"},0), 'Cost Data Sheet'!$B$2:$B$1003, 'Cost Data Sheet'!$C$2:$C$1003, 'Cost Data Sheet'!$D$2:$D$1003, 'Cost Data Sheet'!$E$2:$E$1003 ) ), 0 ) ) ) + MIN( SUMPRODUCT( ('Service to CPT Map'!$A$2:$A$1017=$A5)* ('Service to CPT Map'!$B$2:$B$1017="Low")* ('Service to CPT Map'!$D$2:$D$1017="ASC")* IFERROR( _xlfn.XLOOKUP( 'Service to CPT Map'!$C$2:$C$1017, 'Cost Data Sheet'!$A$2:$A$1003, CHOOSE( MATCH('Master Data'!$B$19, {"Los Angeles","San Diego","San Francisco","Palo Alto"},0), 'Cost Data Sheet'!$B$2:$B$1003, 'Cost Data Sheet'!$C$2:$C$1003, 'Cost Data Sheet'!$D$2:$D$1003, 'Cost Data Sheet'!$E$2:$E$1003 ) ), 0 ) ), SUMPRODUCT( ('Service to CPT Map'!$A$2:$A$1017=$A5)* ('Service to CPT Map'!$B$2:$B$1017="Low")* ('Service to CPT Map'!$D$2:$D$1017="Outpatient")* IFERROR( _xlfn.XLOOKUP( 'Service to CPT Map'!$C$2:$C$1017, 'Cost Data Sheet'!$A$2:$A$1003, CHOOSE( MATCH('Master Data'!$B$19, {"Los Angeles","San Diego","San Francisco","Palo Alto"},0), 'Cost Data Sheet'!$B$2:$B$1003, 'Cost Data Sheet'!$C$2:$C$1003, 'Cost Data Sheet'!$D$2:$D$1003, 'Cost Data Sheet'!$E$2:$E$1003 ) ), 0 ) ) ) ) )} -> 4253 | F5: {=IF( OR($A5="Single Lung Transplant",$A5="Double Lung Transplant"), E5, SUMPRODUCT( ('Service to CPT Map'!$A$2:$A$1017=$A5)* ('Service to CPT Map'!$B$2:$B$1017="High")* ('Service to CPT Map'!$D$2:$D$1017="Medical")* IFERROR( _xlfn.XLOOKUP( 'Service to CPT Map'!$C$2:$C$1017, 'Cost Data Sheet'!$A$2:$A$1003, CHOOSE( MATCH('Master Data'!$B$19, {"Los Angeles","San Diego","San Francisco","Palo Alto"},0), 'Cost Data Sheet'!$B$2:$B$1003, 'Cost Data Sheet'!$C$2:$C$1003, 'Cost Data Sheet'!$D$2:$D$1003, 'Cost Data Sheet'!$E$2:$E$1003 ) ), 0 ) ) + IF( COUNTIFS( 'Service to CPT Map'!$A$2:$A$1017,$A5, 'Service to CPT Map'!$B$2:$B$1017,"High", 'Service to CPT Map'!$D$2:$D$1017,"Anesthesia" )>0, SUMPRODUCT( ('Service to CPT Map'!$A$2:$A$1017=$A5)* ('Service to CPT Map'!$B$2:$B$1017="High")* ('Service to CPT Map'!$D$2:$D$1017="Anesthesia")* IFERROR( _xlfn.XLOOKUP( 'Service to CPT Map'!$C$2:$C$1017, 'Cost Data Sheet'!$A$2:$A$1003, CHOOSE( MATCH('Master Data'!$B$19, {"Los Angeles","San Diego","San Francisco","Palo Alto"},0), 'Cost Data Sheet'!$B$2:$B$1003, 'Cost Data Sheet'!$C$2:$C$1003, 'Cost Data Sheet'!$D$2:$D$1003, 'Cost Data Sheet'!$E$2:$E$1003 ) ), 0 ) ), SUMPRODUCT( ('Service to CPT Map'!$A$2:$A$1017=$A5)* ('Service to CPT Map'!$B$2:$B$1017="High")* ('Service to CPT Map'!$D$2:$D$1017="Medical - Sedation")* IFERROR( _xlfn.XLOOKUP( 'Service to CPT Map'!$C$2:$C$1017, 'Cost Data Sheet'!$A$2:$A$1003, CHOOSE( MATCH('Master Data'!$B$19, {"Los Angeles","San Diego","San Francisco","Palo Alto"},0), 'Cost Data Sheet'!$B$2:$B$1003, 'Cost Data Sheet'!$C$2:$C$1003, 'Cost Data Sheet'!$D$2:$D$1003, 'Cost Data Sheet'!$E$2:$E$1003 ) ), 0 ) ) ) + MAX( SUMPRODUCT( ('Service to CPT Map'!$A$2:$A$1017=$A5)* ('Service to CPT Map'!$B$2:$B$1017="High")* ('Service to CPT Map'!$D$2:$D$1017="ASC")* IFERROR( _xlfn.XLOOKUP( 'Service to CPT Map'!$C$2:$C$1017, 'Cost Data Sheet'!$A$2:$A$1003, CHOOSE( MATCH('Master Data'!$B$19, {"Los Angeles","San Diego","San Francisco","Palo Alto"},0), 'Cost Data Sheet'!$B$2:$B$1003, 'Cost Data Sheet'!$C$2:$C$1003, 'Cost Data Sheet'!$D$2:$D$1003, 'Cost Data Sheet'!$E$2:$E$1003 ) ), 0 ) ), SUMPRODUCT( ('Service to CPT Map'!$A$2:$A$1017=$A5)* ('Service to CPT Map'!$B$2:$B$1017="High")* ('Service to CPT Map'!$D$2:$D$1017="Outpatient")* IFERROR( _xlfn.XLOOKUP( 'Service to CPT Map'!$C$2:$C$1017, 'Cost Data Sheet'!$A$2:$A$1003, CHOOSE( MATCH('Master Data'!$B$19, {"Los Angeles","San Diego","San Francisco","Palo Alto"},0), 'Cost Data Sheet'!$B$2:$B$1003, 'Cost Data Sheet'!$C$2:$C$1003, 'Cost Data Sheet'!$D$2:$D$1003, 'Cost Data Sheet'!$E$2:$E$1003 ) ), 0 ) ) ) )} -> 8085 | G5: =IF(E5<F5,CONCATENATE(TEXT(E5,"$#,##0.00"),CHAR(10)," - ",CHAR(10),TEXT(F5,"$#,##0.00")),TEXT(E5,"$#,##0.00")) -> $4,253.00 - $8,085.00 | H5: 1 | I5: 2 | L5: =IF(LEN(K5)=0,IF(LEN(J5)=0,"lifetime",IF(J5=1,"year","years")),"years") -> lifetime | M5: =IF(L5="lifetime", IF(I5<>"", H5 & "-" & I5 & "x/lifetime", H5 & "x/lifetime"), IF(D5='Master Data'!$B$8, AD5 & AE5, AD5 & AE5 & AC5)) -> 1-2x/lifetime | N5: =ROUND(IF(OR(EXACT(TimeValue,"years"),EXACT(TimeValue,"year")),IF(OR(MinTimePeriod>0,MaxTimePeriod>0),MinFreq*MinCost/(IF(MaxTimePeriod>0,MaxTimePeriod,MinTimePeriod)),0),IF(EXACT(TimeValue,"lifetime"),0,IF(OR(EXACT(TimeValue,"month"),EXACT(TimeValue,"months")),IF(OR(MinTimePeriod>0,MaxTimePeriod>0),MinFreq*MinCost/(IF(MaxTimePeriod>0,MaxTimePeriod/12,MinTimePeriod/12)),0),IF(OR(EXACT(TimeValue,"week"),EXACT(TimeValue,"weeks")),IF(OR(MinTimePeriod>0,MaxTimePeriod>0),MinFreq*MinCost/(IF(MaxTimePeriod>0,MaxTimePeriod/52,MinTimePeriod/52)),0),IF(OR(EXACT(TimeValue,"day"),EXACT(TimeValue,"days")),IF(OR(MinTimePeriod>0,MaxTimePeriod>0),MinFreq*MinCost/(IF(MaxTimePeriod>0,MaxTimePeriod/365,MinTimePeriod/365))),"invalidinput"))))),2) -> 0 | O5: =ROUND(IF(TimeValue="lifetime",0,IF(OR(EXACT(TimeValue,"years"),EXACT(TimeValue,"year")),IF(OR(MinTimePeriod>0,MaxTimePeriod>0),(IF(MaxFreq>0,MaxFreq,MinFreq))*MaxCost/MinTimePeriod),IF(OR(EXACT(TimeValue,"month"),EXACT(TimeValue,"months")),IF(OR(MinTimePeriod>0,MaxTimePeriod>0),(IF(MaxFreq>0,MaxFreq,MinFreq))*MaxCost/(MinTimePeriod/12),0),IF(OR(EXACT(TimeValue,"week"),EXACT(TimeValue,"weeks")),IF(OR(MinTimePeriod>0,MaxTimePeriod>0),IF(MaxFreq>0,MaxFreq,MinFreq))*MaxCost/(MinTimePeriod/52),IF(OR(EXACT(TimeValue,"day"),EXACT(TimeValue,"days")),IF(OR(MinTimePeriod>0,MaxTimePeriod>0),IF(MaxFreq>0,MaxFreq,MinFreq))*MaxCost/(MinTimePeriod/365),"invalidinput"))))),2) -> 0 | P5: =IF(N5<O5,CONCATENATE(TEXT(N5,"$#,###.00"),CHAR(10)," - ",CHAR(10),TEXT(O5,"$#,####.00")),TEXT(N5,"$0.00")) -> $0.00 | Q5: =ROUND(IF(TimeValue="lifetime",MinCost*MinFreq,0),2) -> 4253 | R5: =ROUND(IF(AND(TimeValue="lifetime",MaxFreq<1),MinFreq*MaxCost,IF(AND(TimeValue="lifetime",MaxFreq>=1),MaxFreq*MaxCost,0)),2) -> 16170 | S5: =IF(Q5<R5,CONCATENATE(TEXT(Q5,"$#,##0.00"),CHAR(10)," - ",CHAR(10),TEXT(R5,"$#,##0.00")),TEXT(Q5,"$#,##0.00")) -> $4,253.00 - $16,170.00 | AA5: =IF(L5="lifetime", "one-time cost", IF(D5='Master Data'!$B$8, AD5 & AE5, AD5 & AE5 & AC5)) -> one-time cost | AB5: =IF(L5="lifetime", IF(I5<>"", H5 & "-" & I5 & "x/lifetime", H5 & "x/lifetime"), "ongoing cost") -> 1-2x/lifetime | AC5: =IF(Table14[[#This Row],[Duration (Years):]]<>'Master Data'!$B$8,CONCATENATE(",",CHAR(10),"for ",Table14[[#This Row],[Duration (Years):]]," years"),"lifelong") -> lifelong | AD5: =IF(L5="lifetime", "one-time cost", IF(I5<>"", H5 & "-" & I5 & "x/", H5 & "x/")) -> one-time cost | AE5: =IF(L5="lifetime", "one-time cost", IF(K5<>"", J5 & "-" & K5 & " " & L5, IF(J5>1, J5 & " " & L5, L5))) -> one-time cost
B6: ='Master Data'!$B$6 -> 126.3 | C6: ='Master Data'!$B$7 -> 136.3 | D6: =ROUND(C6-B6,1) -> 10 | E6: {=IF( $A6="Single Lung Transplant", _xlfn.XLOOKUP(1,'Cost Data Sheet'!$A$2:$A$1003,'Cost Data Sheet'!$F$2:$F$1003), IF( $A6="Double Lung Transplant", _xlfn.XLOOKUP(2,'Cost Data Sheet'!$A$2:$A$1003,'Cost Data Sheet'!$F$2:$F$1003), SUMPRODUCT( ('Service to CPT Map'!$A$2:$A$1017=$A6)* ('Service to CPT Map'!$B$2:$B$1017="Low")* ('Service to CPT Map'!$D$2:$D$1017="Medical")* IFERROR( _xlfn.XLOOKUP( 'Service to CPT Map'!$C$2:$C$1017, 'Cost Data Sheet'!$A$2:$A$1003, CHOOSE( MATCH('Master Data'!$B$19, {"Los Angeles","San Diego","San Francisco","Palo Alto"},0), 'Cost Data Sheet'!$B$2:$B$1003, 'Cost Data Sheet'!$C$2:$C$1003, 'Cost Data Sheet'!$D$2:$D$1003, 'Cost Data Sheet'!$E$2:$E$1003 ) ), 0 ) ) + IF( COUNTIFS( 'Service to CPT Map'!$A$2:$A$1017,$A6, 'Service to CPT Map'!$B$2:$B$1017,"Low", 'Service to CPT Map'!$D$2:$D$1017,"Anesthesia" )>0, SUMPRODUCT( ('Service to CPT Map'!$A$2:$A$1017=$A6)* ('Service to CPT Map'!$B$2:$B$1017="Low")* ('Service to CPT Map'!$D$2:$D$1017="Anesthesia")* IFERROR( _xlfn.XLOOKUP( 'Service to CPT Map'!$C$2:$C$1017, 'Cost Data Sheet'!$A$2:$A$1003, CHOOSE( MATCH('Master Data'!$B$19, {"Los Angeles","San Diego","San Francisco","Palo Alto"},0), 'Cost Data Sheet'!$B$2:$B$1003, 'Cost Data Sheet'!$C$2:$C$1003, 'Cost Data Sheet'!$D$2:$D$1003, 'Cost Data Sheet'!$E$2:$E$1003 ) ), 0 ) ), SUMPRODUCT( ('Service to CPT Map'!$A$2:$A$1017=$A6)* ('Service to CPT Map'!$B$2:$B$1017="Low")* ('Service to CPT Map'!$D$2:$D$1017="Medical - Sedation")* IFERROR( _xlfn.XLOOKUP( 'Service to CPT Map'!$C$2:$C$1017, 'Cost Data Sheet'!$A$2:$A$1003, CHOOSE( MATCH('Master Data'!$B$19, {"Los Angeles","San Diego","San Francisco","Palo Alto"},0), 'Cost Data Sheet'!$B$2:$B$1003, 'Cost Data Sheet'!$C$2:$C$1003, 'Cost Data Sheet'!$D$2:$D$1003, 'Cost Data Sheet'!$E$2:$E$1003 ) ), 0 ) ) ) + MIN( SUMPRODUCT( ('Service to CPT Map'!$A$2:$A$1017=$A6)* ('Service to CPT Map'!$B$2:$B$1017="Low")* ('Service to CPT Map'!$D$2:$D$1017="ASC")* IFERROR( _xlfn.XLOOKUP( 'Service to CPT Map'!$C$2:$C$1017, 'Cost Data Sheet'!$A$2:$A$1003, CHOOSE( MATCH('Master Data'!$B$19, {"Los Angeles","San Diego","San Francisco","Palo Alto"},0), 'Cost Data Sheet'!$B$2:$B$1003, 'Cost Data Sheet'!$C$2:$C$1003, 'Cost Data Sheet'!$D$2:$D$1003, 'Cost Data Sheet'!$E$2:$E$1003 ) ), 0 ) ), SUMPRODUCT( ('Service to CPT Map'!$A$2:$A$1017=$A6)* ('Service to CPT Map'!$B$2:$B$1017="Low")* ('Service to CPT Map'!$D$2:$D$1017="Outpatient")* IFERROR( _xlfn.XLOOKUP( 'Service to CPT Map'!$C$2:$C$1017, 'Cost Data Sheet'!$A$2:$A$1003, CHOOSE( MATCH('Master Data'!$B$19, {"Los Angeles","San Diego","San Francisco","Palo Alto"},0), 'Cost Data Sheet'!$B$2:$B$1003, 'Cost Data Sheet'!$C$2:$C$1003, 'Cost Data Sheet'!$D$2:$D$1003, 'Cost Data Sheet'!$E$2:$E$1003 ) ), 0 ) ) ) ) )} -> 0 | F6: {=IF( OR($A6="Single Lung Transplant",$A6="Double Lung Transplant"), E6, SUMPRODUCT( ('Service to CPT Map'!$A$2:$A$1017=$A6)* ('Service to CPT Map'!$B$2:$B$1017="High")* ('Service to CPT Map'!$D$2:$D$1017="Medical")* IFERROR( _xlfn.XLOOKUP( 'Service to CPT Map'!$C$2:$C$1017, 'Cost Data Sheet'!$A$2:$A$1003, CHOOSE( MATCH('Master Data'!$B$19, {"Los Angeles","San Diego","San Francisco","Palo Alto"},0), 'Cost Data Sheet'!$B$2:$B$1003, 'Cost Data Sheet'!$C$2:$C$1003, 'Cost Data Sheet'!$D$2:$D$1003, 'Cost Data Sheet'!$E$2:$E$1003 ) ), 0 ) ) + IF( COUNTIFS( 'Service to CPT Map'!$A$2:$A$1017,$A6, 'Service to CPT Map'!$B$2:$B$1017,"High", 'Service to CPT Map'!$D$2:$D$1017,"Anesthesia" )>0, SUMPRODUCT( ('Service to CPT Map'!$A$2:$A$1017=$A6)* ('Service to CPT Map'!$B$2:$B$1017="High")* ('Service to CPT Map'!$D$2:$D$1017="Anesthesia")* IFERROR( _xlfn.XLOOKUP( 'Service to CPT Map'!$C$2:$C$1017, 'Cost Data Sheet'!$A$2:$A$1003, CHOOSE( MATCH('Master Data'!$B$19, {"Los Angeles","San Diego","San Francisco","Palo Alto"},0), 'Cost Data Sheet'!$B$2:$B$1003, 'Cost Data Sheet'!$C$2:$C$1003, 'Cost Data Sheet'!$D$2:$D$1003, 'Cost Data Sheet'!$E$2:$E$1003 ) ), 0 ) ), SUMPRODUCT( ('Service to CPT Map'!$A$2:$A$1017=$A6)* ('Service to CPT Map'!$B$2:$B$1017="High")* ('Service to CPT Map'!$D$2:$D$1017="Medical - Sedation")* IFERROR( _xlfn.XLOOKUP( 'Service to CPT Map'!$C$2:$C$1017, 'Cost Data Sheet'!$A$2:$A$1003, CHOOSE( MATCH('Master Data'!$B$19, {"Los Angeles","San Diego","San Francisco","Palo Alto"},0), 'Cost Data Sheet'!$B$2:$B$1003, 'Cost Data Sheet'!$C$2:$C$1003, 'Cost Data Sheet'!$D$2:$D$1003, 'Cost Data Sheet'!$E$2:$E$1003 ) ), 0 ) ) ) + MAX( SUMPRODUCT( ('Service to CPT Map'!$A$2:$A$1017=$A6)* ('Service to CPT Map'!$B$2:$B$1017="High")* ('Service to CPT Map'!$D$2:$D$1017="ASC")* IFERROR( _xlfn.XLOOKUP( 'Service to CPT Map'!$C$2:$C$1017, 'Cost Data Sheet'!$A$2:$A$1003, CHOOSE( MATCH('Master Data'!$B$19, {"Los Angeles","San Diego","San Francisco","Palo Alto"},0), 'Cost Data Sheet'!$B$2:$B$1003, 'Cost Data Sheet'!$C$2:$C$1003, 'Cost Data Sheet'!$D$2:$D$1003, 'Cost Data Sheet'!$E$2:$E$1003 ) ), 0 ) ), SUMPRODUCT( ('Service to CPT Map'!$A$2:$A$1017=$A6)* ('Service to CPT Map'!$B$2:$B$1017="High")* ('Service to CPT Map'!$D$2:$D$1017="Outpatient")* IFERROR( _xlfn.XLOOKUP( 'Service to CPT Map'!$C$2:$C$1017, 'Cost Data Sheet'!$A$2:$A$1003, CHOOSE( MATCH('Master Data'!$B$19, {"Los Angeles","San Diego","San Francisco","Palo Alto"},0), 'Cost Data Sheet'!$B$2:$B$1003, 'Cost Data Sheet'!$C$2:$C$1003, 'Cost Data Sheet'!$D$2:$D$1003, 'Cost Data Sheet'!$E$2:$E$1003 ) ), 0 ) ) ) )} -> 0 | G6: =IF(E6<F6,CONCATENATE(TEXT(E6,"$#,##0.00"),CHAR(10)," - ",CHAR(10),TEXT(F6,"$#,##0.00")),TEXT(E6,"$#,##0.00")) -> $0.00 | L6: =IF(LEN(K6)=0,IF(LEN(J6)=0,"lifetime",IF(J6=1,"year","years")),"years") -> lifetime | M6: =IF(L6="lifetime", IF(I6<>"", H6 & "-" & I6 & "x/lifetime", H6 & "x/lifetime"), IF(D6='Master Data'!$B$8, AD6 & AE6, AD6 & AE6 & AC6)) -> x/lifetime | N6: =ROUND(IF(OR(EXACT(TimeValue,"years"),EXACT(TimeValue,"year")),IF(OR(MinTimePeriod>0,MaxTimePeriod>0),MinFreq*MinCost/(IF(MaxTimePeriod>0,MaxTimePeriod,MinTimePeriod)),0),IF(EXACT(TimeValue,"lifetime"),0,IF(OR(EXACT(TimeValue,"month"),EXACT(TimeValue,"months")),IF(OR(MinTimePeriod>0,MaxTimePeriod>0),MinFreq*MinCost/(IF(MaxTimePeriod>0,MaxTimePeriod/12,MinTimePeriod/12)),0),IF(OR(EXACT(TimeValue,"week"),EXACT(TimeValue,"weeks")),IF(OR(MinTimePeriod>0,MaxTimePeriod>0),MinFreq*MinCost/(IF(MaxTimePeriod>0,MaxTimePeriod/52,MinTimePeriod/52)),0),IF(OR(EXACT(TimeValue,"day"),EXACT(TimeValue,"days")),IF(OR(MinTimePeriod>0,MaxTimePeriod>0),MinFreq*MinCost/(IF(MaxTimePeriod>0,MaxTimePeriod/365,MinTimePeriod/365))),"invalidinput"))))),2) -> 0 | O6: =ROUND(IF(TimeValue="lifetime",0,IF(OR(EXACT(TimeValue,"years"),EXACT(TimeValue,"year")),IF(OR(MinTimePeriod>0,MaxTimePeriod>0),(IF(MaxFreq>0,MaxFreq,MinFreq))*MaxCost/MinTimePeriod),IF(OR(EXACT(TimeValue,"month"),EXACT(TimeValue,"months")),IF(OR(MinTimePeriod>0,MaxTimePeriod>0),(IF(MaxFreq>0,MaxFreq,MinFreq))*MaxCost/(MinTimePeriod/12),0),IF(OR(EXACT(TimeValue,"week"),EXACT(TimeValue,"weeks")),IF(OR(MinTimePeriod>0,MaxTimePeriod>0),IF(MaxFreq>0,MaxFreq,MinFreq))*MaxCost/(MinTimePeriod/52),IF(OR(EXACT(TimeValue,"day"),EXACT(TimeValue,"days")),IF(OR(MinTimePeriod>0,MaxTimePeriod>0),IF(MaxFreq>0,MaxFreq,MinFreq))*MaxCost/(MinTimePeriod/365),"invalidinput"))))),2) -> 0 | P6: =IF(N6<O6,CONCATENATE(TEXT(N6,"$#,###.00"),CHAR(10)," - ",CHAR(10),TEXT(O6,"$#,####.00")),TEXT(N6,"$0.00")) -> $0.00 | Q6: =ROUND(IF(TimeValue="lifetime",MinCost*MinFreq,0),2) -> 0 | R6: =ROUND(IF(AND(TimeValue="lifetime",MaxFreq<1),MinFreq*MaxCost,IF(AND(TimeValue="lifetime",MaxFreq>=1),MaxFreq*MaxCost,0)),2) -> 0 | S6: =IF(Q6<R6,CONCATENATE(TEXT(Q6,"$#,##0.00"),CHAR(10)," - ",CHAR(10),TEXT(R6,"$#,##0.00")),TEXT(Q6,"$#,##0.00")) -> $0.00 | AA6: =IF(L6="lifetime", "one-time cost", IF(D6='Master Data'!$B$8, AD6 & AE6, AD6 & AE6 & AC6)) -> one-time cost | AB6: =IF(L6="lifetime", IF(I6<>"", H6 & "-" & I6 & "x/lifetime", H6 & "x/lifetime"), "ongoing cost") -> x/lifetime | AC6: =IF(Table14[[#This Row],[Duration (Years):]]<>'Master Data'!$B$8,CONCATENATE(",",CHAR(10),"for ",Table14[[#This Row],[Duration (Years):]]," years"),"lifelong") -> lifelong | AD6: =IF(L6="lifetime", "one-time cost", IF(I6<>"", H6 & "-" & I6 & "x/", H6 & "x/")) -> one-time cost | AE6: =IF(L6="lifetime", "one-time cost", IF(K6<>"", J6 & "-" & K6 & " " & L6, IF(J6>1, J6 & " " & L6, L6))) -> one-time cost
B7: ='Master Data'!$B$6 -> 126.3 | C7: ='Master Data'!$B$7 -> 136.3 | D7: =ROUND(C7-B7,1) -> 10 | E7: {=IF( $A7="Single Lung Transplant", _xlfn.XLOOKUP(1,'Cost Data Sheet'!$A$2:$A$1003,'Cost Data Sheet'!$F$2:$F$1003), IF( $A7="Double Lung Transplant", _xlfn.XLOOKUP(2,'Cost Data Sheet'!$A$2:$A$1003,'Cost Data Sheet'!$F$2:$F$1003), SUMPRODUCT( ('Service to CPT Map'!$A$2:$A$1017=$A7)* ('Service to CPT Map'!$B$2:$B$1017="Low")* ('Service to CPT Map'!$D$2:$D$1017="Medical")* IFERROR( _xlfn.XLOOKUP( 'Service to CPT Map'!$C$2:$C$1017, 'Cost Data Sheet'!$A$2:$A$1003, CHOOSE( MATCH('Master Data'!$B$19, {"Los Angeles","San Diego","San Francisco","Palo Alto"},0), 'Cost Data Sheet'!$B$2:$B$1003, 'Cost Data Sheet'!$C$2:$C$1003, 'Cost Data Sheet'!$D$2:$D$1003, 'Cost Data Sheet'!$E$2:$E$1003 ) ), 0 ) ) + IF( COUNTIFS( 'Service to CPT Map'!$A$2:$A$1017,$A7, 'Service to CPT Map'!$B$2:$B$1017,"Low", 'Service to CPT Map'!$D$2:$D$1017,"Anesthesia" )>0, SUMPRODUCT( ('Service to CPT Map'!$A$2:$A$1017=$A7)* ('Service to CPT Map'!$B$2:$B$1017="Low")* ('Service to CPT Map'!$D$2:$D$1017="Anesthesia")* IFERROR( _xlfn.XLOOKUP( 'Service to CPT Map'!$C$2:$C$1017, 'Cost Data Sheet'!$A$2:$A$1003, CHOOSE( MATCH('Master Data'!$B$19, {"Los Angeles","San Diego","San Francisco","Palo Alto"},0), 'Cost Data Sheet'!$B$2:$B$1003, 'Cost Data Sheet'!$C$2:$C$1003, 'Cost Data Sheet'!$D$2:$D$1003, 'Cost Data Sheet'!$E$2:$E$1003 ) ), 0 ) ), SUMPRODUCT( ('Service to CPT Map'!$A$2:$A$1017=$A7)* ('Service to CPT Map'!$B$2:$B$1017="Low")* ('Service to CPT Map'!$D$2:$D$1017="Medical - Sedation")* IFERROR( _xlfn.XLOOKUP( 'Service to CPT Map'!$C$2:$C$1017, 'Cost Data Sheet'!$A$2:$A$1003, CHOOSE( MATCH('Master Data'!$B$19, {"Los Angeles","San Diego","San Francisco","Palo Alto"},0), 'Cost Data Sheet'!$B$2:$B$1003, 'Cost Data Sheet'!$C$2:$C$1003, 'Cost Data Sheet'!$D$2:$D$1003, 'Cost Data Sheet'!$E$2:$E$1003 ) ), 0 ) ) ) + MIN( SUMPRODUCT( ('Service to CPT Map'!$A$2:$A$1017=$A7)* ('Service to CPT Map'!$B$2:$B$1017="Low")* ('Service to CPT Map'!$D$2:$D$1017="ASC")* IFERROR( _xlfn.XLOOKUP( 'Service to CPT Map'!$C$2:$C$1017, 'Cost Data Sheet'!$A$2:$A$1003, CHOOSE( MATCH('Master Data'!$B$19, {"Los Angeles","San Diego","San Francisco","Palo Alto"},0), 'Cost Data Sheet'!$B$2:$B$1003, 'Cost Data Sheet'!$C$2:$C$1003, 'Cost Data Sheet'!$D$2:$D$1003, 'Cost Data Sheet'!$E$2:$E$1003 ) ), 0 ) ), SUMPRODUCT( ('Service to CPT Map'!$A$2:$A$1017=$A7)* ('Service to CPT Map'!$B$2:$B$1017="Low")* ('Service to CPT Map'!$D$2:$D$1017="Outpatient")* IFERROR( _xlfn.XLOOKUP( 'Service to CPT Map'!$C$2:$C$1017, 'Cost Data Sheet'!$A$2:$A$1003, CHOOSE( MATCH('Master Data'!$B$19, {"Los Angeles","San Diego","San Francisco","Palo Alto"},0), 'Cost Data Sheet'!$B$2:$B$1003, 'Cost Data Sheet'!$C$2:$C$1003, 'Cost Data Sheet'!$D$2:$D$1003, 'Cost Data Sheet'!$E$2:$E$1003 ) ), 0 ) ) ) ) )} -> 0 | F7: {=IF( OR($A7="Single Lung Transplant",$A7="Double Lung Transplant"), E7, SUMPRODUCT( ('Service to CPT Map'!$A$2:$A$1017=$A7)* ('Service to CPT Map'!$B$2:$B$1017="High")* ('Service to CPT Map'!$D$2:$D$1017="Medical")* IFERROR( _xlfn.XLOOKUP( 'Service to CPT Map'!$C$2:$C$1017, 'Cost Data Sheet'!$A$2:$A$1003, CHOOSE( MATCH('Master Data'!$B$19, {"Los Angeles","San Diego","San Francisco","Palo Alto"},0), 'Cost Data Sheet'!$B$2:$B$1003, 'Cost Data Sheet'!$C$2:$C$1003, 'Cost Data Sheet'!$D$2:$D$1003, 'Cost Data Sheet'!$E$2:$E$1003 ) ), 0 ) ) + IF( COUNTIFS( 'Service to CPT Map'!$A$2:$A$1017,$A7, 'Service to CPT Map'!$B$2:$B$1017,"High", 'Service to CPT Map'!$D$2:$D$1017,"Anesthesia" )>0, SUMPRODUCT( ('Service to CPT Map'!$A$2:$A$1017=$A7)* ('Service to CPT Map'!$B$2:$B$1017="High")* ('Service to CPT Map'!$D$2:$D$1017="Anesthesia")* IFERROR( _xlfn.XLOOKUP( 'Service to CPT Map'!$C$2:$C$1017, 'Cost Data Sheet'!$A$2:$A$1003, CHOOSE( MATCH('Master Data'!$B$19, {"Los Angeles","San Diego","San Francisco","Palo Alto"},0), 'Cost Data Sheet'!$B$2:$B$1003, 'Cost Data Sheet'!$C$2:$C$1003, 'Cost Data Sheet'!$D$2:$D$1003, 'Cost Data Sheet'!$E$2:$E$1003 ) ), 0 ) ), SUMPRODUCT( ('Service to CPT Map'!$A$2:$A$1017=$A7)* ('Service to CPT Map'!$B$2:$B$1017="High")* ('Service to CPT Map'!$D$2:$D$1017="Medical - Sedation")* IFERROR( _xlfn.XLOOKUP( 'Service to CPT Map'!$C$2:$C$1017, 'Cost Data Sheet'!$A$2:$A$1003, CHOOSE( MATCH('Master Data'!$B$19, {"Los Angeles","San Diego","San Francisco","Palo Alto"},0), 'Cost Data Sheet'!$B$2:$B$1003, 'Cost Data Sheet'!$C$2:$C$1003, 'Cost Data Sheet'!$D$2:$D$1003, 'Cost Data Sheet'!$E$2:$E$1003 ) ), 0 ) ) ) + MAX( SUMPRODUCT( ('Service to CPT Map'!$A$2:$A$1017=$A7)* ('Service to CPT Map'!$B$2:$B$1017="High")* ('Service to CPT Map'!$D$2:$D$1017="ASC")* IFERROR( _xlfn.XLOOKUP( 'Service to CPT Map'!$C$2:$C$1017, 'Cost Data Sheet'!$A$2:$A$1003, CHOOSE( MATCH('Master Data'!$B$19, {"Los Angeles","San Diego","San Francisco","Palo Alto"},0), 'Cost Data Sheet'!$B$2:$B$1003, 'Cost Data Sheet'!$C$2:$C$1003, 'Cost Data Sheet'!$D$2:$D$1003, 'Cost Data Sheet'!$E$2:$E$1003 ) ), 0 ) ), SUMPRODUCT( ('Service to CPT Map'!$A$2:$A$1017=$A7)* ('Service to CPT Map'!$B$2:$B$1017="High")* ('Service to CPT Map'!$D$2:$D$1017="Outpatient")* IFERROR( _xlfn.XLOOKUP( 'Service to CPT Map'!$C$2:$C$1017, 'Cost Data Sheet'!$A$2:$A$1003, CHOOSE( MATCH('Master Data'!$B$19, {"Los Angeles","San Diego","San Francisco","Palo Alto"},0), 'Cost Data Sheet'!$B$2:$B$1003, 'Cost Data Sheet'!$C$2:$C$1003, 'Cost Data Sheet'!$D$2:$D$1003, 'Cost Data Sheet'!$E$2:$E$1003 ) ), 0 ) ) ) )} -> 0 | G7: =IF(E7<F7,CONCATENATE(TEXT(E7,"$#,##0.00"),CHAR(10)," - ",CHAR(10),TEXT(F7,"$#,##0.00")),TEXT(E7,"$#,##0.00")) -> $0.00 | L7: =IF(LEN(K7)=0,IF(LEN(J7)=0,"lifetime",IF(J7=1,"year","years")),"years") -> lifetime | M7: =IF(L7="lifetime", IF(I7<>"", H7 & "-" & I7 & "x/lifetime", H7 & "x/lifetime"), IF(D7='Master Data'!$B$8, AD7 & AE7, AD7 & AE7 & AC7)) -> x/lifetime | N7: =ROUND(IF(OR(EXACT(TimeValue,"years"),EXACT(TimeValue,"year")),IF(OR(MinTimePeriod>0,MaxTimePeriod>0),MinFreq*MinCost/(IF(MaxTimePeriod>0,MaxTimePeriod,MinTimePeriod)),0),IF(EXACT(TimeValue,"lifetime"),0,IF(OR(EXACT(TimeValue,"month"),EXACT(TimeValue,"months")),IF(OR(MinTimePeriod>0,MaxTimePeriod>0),MinFreq*MinCost/(IF(MaxTimePeriod>0,MaxTimePeriod/12,MinTimePeriod/12)),0),IF(OR(EXACT(TimeValue,"week"),EXACT(TimeValue,"weeks")),IF(OR(MinTimePeriod>0,MaxTimePeriod>0),MinFreq*MinCost/(IF(MaxTimePeriod>0,MaxTimePeriod/52,MinTimePeriod/52)),0),IF(OR(EXACT(TimeValue,"day"),EXACT(TimeValue,"days")),IF(OR(MinTimePeriod>0,MaxTimePeriod>0),MinFreq*MinCost/(IF(MaxTimePeriod>0,MaxTimePeriod/365,MinTimePeriod/365))),"invalidinput"))))),2) -> 0 | O7: =ROUND(IF(TimeValue="lifetime",0,IF(OR(EXACT(TimeValue,"years"),EXACT(TimeValue,"year")),IF(OR(MinTimePeriod>0,MaxTimePeriod>0),(IF(MaxFreq>0,MaxFreq,MinFreq))*MaxCost/MinTimePeriod),IF(OR(EXACT(TimeValue,"month"),EXACT(TimeValue,"months")),IF(OR(MinTimePeriod>0,MaxTimePeriod>0),(IF(MaxFreq>0,MaxFreq,MinFreq))*MaxCost/(MinTimePeriod/12),0),IF(OR(EXACT(TimeValue,"week"),EXACT(TimeValue,"weeks")),IF(OR(MinTimePeriod>0,MaxTimePeriod>0),IF(MaxFreq>0,MaxFreq,MinFreq))*MaxCost/(MinTimePeriod/52),IF(OR(EXACT(TimeValue,"day"),EXACT(TimeValue,"days")),IF(OR(MinTimePeriod>0,MaxTimePeriod>0),IF(MaxFreq>0,MaxFreq,MinFreq))*MaxCost/(MinTimePeriod/365),"invalidinput"))))),2) -> 0 | P7: =IF(N7<O7,CONCATENATE(TEXT(N7,"$#,###.00"),CHAR(10)," - ",CHAR(10),TEXT(O7,"$#,####.00")),TEXT(N7,"$0.00")) -> $0.00 | Q7: =ROUND(IF(TimeValue="lifetime",MinCost*MinFreq,0),2) -> 0 | R7: =ROUND(IF(AND(TimeValue="lifetime",MaxFreq<1),MinFreq*MaxCost,IF(AND(TimeValue="lifetime",MaxFreq>=1),MaxFreq*MaxCost,0)),2) -> 0 | S7: =IF(Q7<R7,CONCATENATE(TEXT(Q7,"$#,##0.00"),CHAR(10)," - ",CHAR(10),TEXT(R7,"$#,##0.00")),TEXT(Q7,"$#,##0.00")) -> $0.00 | AA7: =IF(L7="lifetime", "one-time cost", IF(D7='Master Data'!$B$8, AD7 & AE7, AD7 & AE7 & AC7)) -> one-time cost | AB7: =IF(L7="lifetime", IF(I7<>"", H7 & "-" & I7 & "x/lifetime", H7 & "x/lifetime"), "ongoing cost") -> x/lifetime | AC7: =IF(Table14[[#This Row],[Duration (Years):]]<>'Master Data'!$B$8,CONCATENATE(",",CHAR(10),"for ",Table14[[#This Row],[Duration (Years):]]," years"),"lifelong") -> lifelong | AD7: =IF(L7="lifetime", "one-time cost", IF(I7<>"", H7 & "-" & I7 & "x/", H7 & "x/")) -> one-time cost | AE7: =IF(L7="lifetime", "one-time cost", IF(K7<>"", J7 & "-" & K7 & " " & L7, IF(J7>1, J7 & " " & L7, L7))) -> one-time cost
B8: ='Master Data'!$B$6 -> 126.3 | C8: ='Master Data'!$B$7 -> 136.3 | D8: =ROUND(C8-B8,1) -> 10 | E8: {=IF( $A8="Single Lung Transplant", _xlfn.XLOOKUP(1,'Cost Data Sheet'!$A$2:$A$1003,'Cost Data Sheet'!$F$2:$F$1003), IF( $A8="Double Lung Transplant", _xlfn.XLOOKUP(2,'Cost Data Sheet'!$A$2:$A$1003,'Cost Data Sheet'!$F$2:$F$1003), SUMPRODUCT( ('Service to CPT Map'!$A$2:$A$1017=$A8)* ('Service to CPT Map'!$B$2:$B$1017="Low")* ('Service to CPT Map'!$D$2:$D$1017="Medical")* IFERROR( _xlfn.XLOOKUP( 'Service to CPT Map'!$C$2:$C$1017, 'Cost Data Sheet'!$A$2:$A$1003, CHOOSE( MATCH('Master Data'!$B$19, {"Los Angeles","San Diego","San Francisco","Palo Alto"},0), 'Cost Data Sheet'!$B$2:$B$1003, 'Cost Data Sheet'!$C$2:$C$1003, 'Cost Data Sheet'!$D$2:$D$1003, 'Cost Data Sheet'!$E$2:$E$1003 ) ), 0 ) ) + IF( COUNTIFS( 'Service to CPT Map'!$A$2:$A$1017,$A8, 'Service to CPT Map'!$B$2:$B$1017,"Low", 'Service to CPT Map'!$D$2:$D$1017,"Anesthesia" )>0, SUMPRODUCT( ('Service to CPT Map'!$A$2:$A$1017=$A8)* ('Service to CPT Map'!$B$2:$B$1017="Low")* ('Service to CPT Map'!$D$2:$D$1017="Anesthesia")* IFERROR( _xlfn.XLOOKUP( 'Service to CPT Map'!$C$2:$C$1017, 'Cost Data Sheet'!$A$2:$A$1003, CHOOSE( MATCH('Master Data'!$B$19, {"Los Angeles","San Diego","San Francisco","Palo Alto"},0), 'Cost Data Sheet'!$B$2:$B$1003, 'Cost Data Sheet'!$C$2:$C$1003, 'Cost Data Sheet'!$D$2:$D$1003, 'Cost Data Sheet'!$E$2:$E$1003 ) ), 0 ) ), SUMPRODUCT( ('Service to CPT Map'!$A$2:$A$1017=$A8)* ('Service to CPT Map'!$B$2:$B$1017="Low")* ('Service to CPT Map'!$D$2:$D$1017="Medical - Sedation")* IFERROR( _xlfn.XLOOKUP( 'Service to CPT Map'!$C$2:$C$1017, 'Cost Data Sheet'!$A$2:$A$1003, CHOOSE( MATCH('Master Data'!$B$19, {"Los Angeles","San Diego","San Francisco","Palo Alto"},0), 'Cost Data Sheet'!$B$2:$B$1003, 'Cost Data Sheet'!$C$2:$C$1003, 'Cost Data Sheet'!$D$2:$D$1003, 'Cost Data Sheet'!$E$2:$E$1003 ) ), 0 ) ) ) + MIN( SUMPRODUCT( ('Service to CPT Map'!$A$2:$A$1017=$A8)* ('Service to CPT Map'!$B$2:$B$1017="Low")* ('Service to CPT Map'!$D$2:$D$1017="ASC")* IFERROR( _xlfn.XLOOKUP( 'Service to CPT Map'!$C$2:$C$1017, 'Cost Data Sheet'!$A$2:$A$1003, CHOOSE( MATCH('Master Data'!$B$19, {"Los Angeles","San Diego","San Francisco","Palo Alto"},0), 'Cost Data Sheet'!$B$2:$B$1003, 'Cost Data Sheet'!$C$2:$C$1003, 'Cost Data Sheet'!$D$2:$D$1003, 'Cost Data Sheet'!$E$2:$E$1003 ) ), 0 ) ), SUMPRODUCT( ('Service to CPT Map'!$A$2:$A$1017=$A8)* ('Service to CPT Map'!$B$2:$B$1017="Low")* ('Service to CPT Map'!$D$2:$D$1017="Outpatient")* IFERROR( _xlfn.XLOOKUP( 'Service to CPT Map'!$C$2:$C$1017, 'Cost Data Sheet'!$A$2:$A$1003, CHOOSE( MATCH('Master Data'!$B$19, {"Los Angeles","San Diego","San Francisco","Palo Alto"},0), 'Cost Data Sheet'!$B$2:$B$1003, 'Cost Data Sheet'!$C$2:$C$1003, 'Cost Data Sheet'!$D$2:$D$1003, 'Cost Data Sheet'!$E$2:$E$1003 ) ), 0 ) ) ) ) )} -> 0 | F8: {=IF( OR($A8="Single Lung Transplant",$A8="Double Lung Transplant"), E8, SUMPRODUCT( ('Service to CPT Map'!$A$2:$A$1017=$A8)* ('Service to CPT Map'!$B$2:$B$1017="High")* ('Service to CPT Map'!$D$2:$D$1017="Medical")* IFERROR( _xlfn.XLOOKUP( 'Service to CPT Map'!$C$2:$C$1017, 'Cost Data Sheet'!$A$2:$A$1003, CHOOSE( MATCH('Master Data'!$B$19, {"Los Angeles","San Diego","San Francisco","Palo Alto"},0), 'Cost Data Sheet'!$B$2:$B$1003, 'Cost Data Sheet'!$C$2:$C$1003, 'Cost Data Sheet'!$D$2:$D$1003, 'Cost Data Sheet'!$E$2:$E$1003 ) ), 0 ) ) + IF( COUNTIFS( 'Service to CPT Map'!$A$2:$A$1017,$A8, 'Service to CPT Map'!$B$2:$B$1017,"High", 'Service to CPT Map'!$D$2:$D$1017,"Anesthesia" )>0, SUMPRODUCT( ('Service to CPT Map'!$A$2:$A$1017=$A8)* ('Service to CPT Map'!$B$2:$B$1017="High")* ('Service to CPT Map'!$D$2:$D$1017="Anesthesia")* IFERROR( _xlfn.XLOOKUP( 'Service to CPT Map'!$C$2:$C$1017, 'Cost Data Sheet'!$A$2:$A$1003, CHOOSE( MATCH('Master Data'!$B$19, {"Los Angeles","San Diego","San Francisco","Palo Alto"},0), 'Cost Data Sheet'!$B$2:$B$1003, 'Cost Data Sheet'!$C$2:$C$1003, 'Cost Data Sheet'!$D$2:$D$1003, 'Cost Data Sheet'!$E$2:$E$1003 ) ), 0 ) ), SUMPRODUCT( ('Service to CPT Map'!$A$2:$A$1017=$A8)* ('Service to CPT Map'!$B$2:$B$1017="High")* ('Service to CPT Map'!$D$2:$D$1017="Medical - Sedation")* IFERROR( _xlfn.XLOOKUP( 'Service to CPT Map'!$C$2:$C$1017, 'Cost Data Sheet'!$A$2:$A$1003, CHOOSE( MATCH('Master Data'!$B$19, {"Los Angeles","San Diego","San Francisco","Palo Alto"},0), 'Cost Data Sheet'!$B$2:$B$1003, 'Cost Data Sheet'!$C$2:$C$1003, 'Cost Data Sheet'!$D$2:$D$1003, 'Cost Data Sheet'!$E$2:$E$1003 ) ), 0 ) ) ) + MAX( SUMPRODUCT( ('Service to CPT Map'!$A$2:$A$1017=$A8)* ('Service to CPT Map'!$B$2:$B$1017="High")* ('Service to CPT Map'!$D$2:$D$1017="ASC")* IFERROR( _xlfn.XLOOKUP( 'Service to CPT Map'!$C$2:$C$1017, 'Cost Data Sheet'!$A$2:$A$1003, CHOOSE( MATCH('Master Data'!$B$19, {"Los Angeles","San Diego","San Francisco","Palo Alto"},0), 'Cost Data Sheet'!$B$2:$B$1003, 'Cost Data Sheet'!$C$2:$C$1003, 'Cost Data Sheet'!$D$2:$D$1003, 'Cost Data Sheet'!$E$2:$E$1003 ) ), 0 ) ), SUMPRODUCT( ('Service to CPT Map'!$A$2:$A$1017=$A8)* ('Service to CPT Map'!$B$2:$B$1017="High")* ('Service to CPT Map'!$D$2:$D$1017="Outpatient")* IFERROR( _xlfn.XLOOKUP( 'Service to CPT Map'!$C$2:$C$1017, 'Cost Data Sheet'!$A$2:$A$1003, CHOOSE( MATCH('Master Data'!$B$19, {"Los Angeles","San Diego","San Francisco","Palo Alto"},0), 'Cost Data Sheet'!$B$2:$B$1003, 'Cost Data Sheet'!$C$2:$C$1003, 'Cost Data Sheet'!$D$2:$D$1003, 'Cost Data Sheet'!$E$2:$E$1003 ) ), 0 ) ) ) )} -> 0 | G8: =IF(E8<F8,CONCATENATE(TEXT(E8,"$#,##0.00"),CHAR(10)," - ",CHAR(10),TEXT(F8,"$#,##0.00")),TEXT(E8,"$#,##0.00")) -> $0.00 | L8: =IF(LEN(K8)=0,IF(LEN(J8)=0,"lifetime",IF(J8=1,"year","years")),"years") -> lifetime | M8: =IF(L8="lifetime", IF(I8<>"", H8 & "-" & I8 & "x/lifetime", H8 & "x/lifetime"), IF(D8='Master Data'!$B$8, AD8 & AE8, AD8 & AE8 & AC8)) -> x/lifetime | N8: =ROUND(IF(OR(EXACT(TimeValue,"years"),EXACT(TimeValue,"year")),IF(OR(MinTimePeriod>0,MaxTimePeriod>0),MinFreq*MinCost/(IF(MaxTimePeriod>0,MaxTimePeriod,MinTimePeriod)),0),IF(EXACT(TimeValue,"lifetime"),0,IF(OR(EXACT(TimeValue,"month"),EXACT(TimeValue,"months")),IF(OR(MinTimePeriod>0,MaxTimePeriod>0),MinFreq*MinCost/(IF(MaxTimePeriod>0,MaxTimePeriod/12,MinTimePeriod/12)),0),IF(OR(EXACT(TimeValue,"week"),EXACT(TimeValue,"weeks")),IF(OR(MinTimePeriod>0,MaxTimePeriod>0),MinFreq*MinCost/(IF(MaxTimePeriod>0,MaxTimePeriod/52,MinTimePeriod/52)),0),IF(OR(EXACT(TimeValue,"day"),EXACT(TimeValue,"days")),IF(OR(MinTimePeriod>0,MaxTimePeriod>0),MinFreq*MinCost/(IF(MaxTimePeriod>0,MaxTimePeriod/365,MinTimePeriod/365))),"invalidinput"))))),2) -> 0 | O8: =ROUND(IF(TimeValue="lifetime",0,IF(OR(EXACT(TimeValue,"years"),EXACT(TimeValue,"year")),IF(OR(MinTimePeriod>0,MaxTimePeriod>0),(IF(MaxFreq>0,MaxFreq,MinFreq))*MaxCost/MinTimePeriod),IF(OR(EXACT(TimeValue,"month"),EXACT(TimeValue,"months")),IF(OR(MinTimePeriod>0,MaxTimePeriod>0),(IF(MaxFreq>0,MaxFreq,MinFreq))*MaxCost/(MinTimePeriod/12),0),IF(OR(EXACT(TimeValue,"week"),EXACT(TimeValue,"weeks")),IF(OR(MinTimePeriod>0,MaxTimePeriod>0),IF(MaxFreq>0,MaxFreq,MinFreq))*MaxCost/(MinTimePeriod/52),IF(OR(EXACT(TimeValue,"day"),EXACT(TimeValue,"days")),IF(OR(MinTimePeriod>0,MaxTimePeriod>0),IF(MaxFreq>0,MaxFreq,MinFreq))*MaxCost/(MinTimePeriod/365),"invalidinput"))))),2) -> 0 | P8: =IF(N8<O8,CONCATENATE(TEXT(N8,"$#,###.00"),CHAR(10)," - ",CHAR(10),TEXT(O8,"$#,####.00")),TEXT(N8,"$0.00")) -> $0.00 | Q8: =ROUND(IF(TimeValue="lifetime",MinCost*MinFreq,0),2) -> 0 | R8: =ROUND(IF(AND(TimeValue="lifetime",MaxFreq<1),MinFreq*MaxCost,IF(AND(TimeValue="lifetime",MaxFreq>=1),MaxFreq*MaxCost,0)),2) -> 0 | S8: =IF(Q8<R8,CONCATENATE(TEXT(Q8,"$#,##0.00"),CHAR(10)," - ",CHAR(10),TEXT(R8,"$#,##0.00")),TEXT(Q8,"$#,##0.00")) -> $0.00 | AA8: =IF(L8="lifetime", "one-time cost", IF(D8='Master Data'!$B$8, AD8 & AE8, AD8 & AE8 & AC8)) -> one-time cost | AB8: =IF(L8="lifetime", IF(I8<>"", H8 & "-" & I8 & "x/lifetime", H8 & "x/lifetime"), "ongoing cost") -> x/lifetime | AC8: =IF(Table14[[#This Row],[Duration (Years):]]<>'Master Data'!$B$8,CONCATENATE(",",CHAR(10),"for ",Table14[[#This Row],[Duration (Years):]]," years"),"lifelong") -> lifelong | AD8: =IF(L8="lifetime", "one-time cost", IF(I8<>"", H8 & "-" & I8 & "x/", H8 & "x/")) -> one-time cost | AE8: =IF(L8="lifetime", "one-time cost", IF(K8<>"", J8 & "-" & K8 & " " & L8, IF(J8>1, J8 & " " & L8, L8))) -> one-time cost
